Workbook

Sheet ARRAY
C5: No. Seri | D5: No | E5: Merk | F5: Type | G5: Tanggal Kalibrasi | H5: Tertelusur | I5: Tegangan | K5: Arus DC (µA) | M5: Arus AC (µA) | O5: Resistansi Pembumian (Ω) | Q5: Resistansi Isolasi (MΩ)
I6: Intercept | J6: Variabel X | K6: Intercept | L6: Variabel X | M6: Intercept | N6: Variabel X | O6: Intercept | P6: Variabel X | Q6: Intercept | R6: Variabel X
C7: =Regresi!C5 -> 6579027 | D7: 1 | E7: =Regresi!C3 -> Fluke Biomedical | F7: =Regresi!C4 -> ESA16 | G7: =Regresi!C6 -> 45819 | H7: =Regresi!C7 -> LK-110-IDN | I7: =Regresi!D47 -> 0.18884844 | J7: =Regresi!D48 -> 0.99976434 | K7: =Regresi!N47 -> 0.0083113755 | L7: =Regresi!N48 -> 0.9979839 | M7: =Regresi!N68 -> 0.011092761 | N7: =Regresi!N69 -> 1.0019062 | O7: =Regresi!D67 -> -0.0084833374 | P7: =Regresi!D68 -> 1.0005092 | Q7: =Regresi!D87 -> 0 | R7: =Regresi!D88 -> 1

Sheet Regresi
A2: Nama | B2: : | C2: ESA
A3: Merk | B3: : | C3: Fluke Biomedical
A4: Tipe | B4: : | C4: ESA16
A5: No.Seri | B5: : | C5: 6579027
A6: Tgl. Kalibrasi | B6: : | C6: 45819
A7: Tertelusur | B7: : | C7: LK-110-IDN
C12: Tegangan (V) | H12: Arus DC (uA) | M12: Arus AC (uA)
C13: Setting Standar | D13: Penunjukan Alat | E13: Koreksi | F13: Ketidakpastian (±) | H13: Setting Standar | I13: Penunjukan Alat | J13: Koreksi | K13: Ketidakpastian (±) | M13: Setting Standar | N13: Penunjukan Alat | O13: Koreksi | P13: Ketidakpastian (±)
C14: 100 | D14: =C14-E14 -> 99.8 | E14: 0.2 | F14: 0.19 | H14: 10 | I14: =H14-J14 -> 10 | J14: 0 | K14: 0.073 | M14: 10 | N14: =M14-O14 -> 9.8 | O14: 0.2 | P14: 0.62
C15: 110 | D15: =C15-E15 -> 109.8 | E15: 0.2 | F15: 0.19 | H15: 50 | I15: =H15-J15 -> 50.1 | J15: -0.1 | K15: 0.073 | M15: 50 | N15: =M15-O15 -> 49.9 | O15: 0.1 | P15: 0.62
C16: 120 | D16: =C16-E16 -> 119.9 | E16: 0.1 | F16: 0.19 | H16: 100 | I16: =H16-J16 -> 100.2 | J16: -0.2 | K16: 0.073 | M16: 100 | N16: =M16-O16 -> 100 | O16: 0 | P16: 0.62
C17: 200 | D17: =C17-E17 -> 199.9 | E17: 0.1 | F17: 0.19 | H17: 500 | I17: =H17-J17 -> 501 | J17: -1 | K17: 0.58 | M17: 500 | N17: =M17-O17 -> 499 | O17: 1 | P17: 0.79
C18: 220 | D18: =C18-E18 -> 219.9 | E18: 0.1 | F18: 0.19
C19: 240 | D19: =C19-E19 -> 239.8 | E19: 0.2 | F19: 0.19
C22: Resistansi Pembumian (Ω) | H22: Resistansi Isolasi (MΩ)
C23: Setting Standar | D23: Penunjukan Alat | E23: Koreksi | F23: Ketidakpastian (±) | H23: Setting Standar | I23: Penunjukan Alat | J23: Koreksi | K23: Ketidakpastian (±)
C24: 0.1 | D24: =C24-E24 -> 0.108 | E24: -0.008 | F24: 0.0025 | H24: 1 | I24: =H24-J24 -> 1 | J24: 0 | K24: 0.058
C25: 0.2 | D25: =C25-E25 -> 0.209 | E25: -0.009 | F25: 0.0025 | H25: 10 | I25: =H25-J25 -> 10 | J25: 0 | K25: 0.058
C26: 0.5 | D26: =C26-E26 -> 0.508 | E26: -0.008 | F26: 0.0025
C27: 1 | D27: =C27-E27 -> 1.008 | E27: -0.008 | F27: 0.0027
C30: Tegangan (V) | M30: Arus DC (uA)
C31: SUMMARY OUTPUT | M31: SUMMARY OUTPUT
C33: Regression Statistics | M33: Regression Statistics
C34: Multiple R | D34: 0.99999964 | M34: Multiple R | N34: 1
C35: R Square | D35: 0.99999927 | M35: R Square | N35: 1
C36: Adjusted R Square | D36: 0.99999909 | M36: Adjusted R Square | N36: 1
C37: Standard Error | D37: 0.059025415 | M37: Standard Error | N37: 0.010874719
C38: Observations | D38: 6 | M38: Observations | N38: 4
C40: ANOVA | M40: ANOVA
D41: df | E41: SS | F41: MS | G41: F | H41: Significance F | N41: df | O41: SS | P41: MS | Q41: F | R41: Significance F
C42: Regression | D42: 1 | E42: 19149.986 | F42: 19149.986 | G42: 5496552.4 | H42: 1.9859577e-13 | M42: Regression | N42: 1 | O42: 153700 | P42: 153700 | Q42: 1.2996841e+09 | R42: 7.6941776e-10
C43: Residual | D43: 4 | E43: 0.013935998 | F43: 0.0034839996 | M43: Residual | N43: 2 | O43: 0.00023651902 | P43: 0.00011825951
C44: Total | D44: 5 | E44: 19150 | M44: Total | N44: 3 | O44: 153700
D46: Coefficients | E46: Standard Error | F46: t Stat | G46: P-value | H46: Lower 95% | I46: Upper 95% | J46: Lower 95,0% | K46: Upper 95,0% | N46: Coefficients | O46: Standard Error | P46: t Stat | Q46: P-value | R46: Lower 95% | S46: Upper 95% | T46: Lower 95,0% | U46: Upper 95,0%
C47: Intercept | D47: 0.18884844 | E47: 0.074313121 | F47: 2.5412529 | G47: 0.063895824 | H47: -0.017477865 | I47: 0.39517473 | J47: -0.017477865 | K47: 0.39517473 | M47: Intercept | N47: 0.0083113755 | O47: 0.0071070504 | P47: 1.169455 | Q47: 0.36273268 | R47: -0.022267794 | S47: 0.038890545 | T47: -0.022267794 | U47: 0.038890545
C48: X Variable 1 | D48: 0.99976434 | E48: 0.00042643462 | F48: 2344.4727 | G48: 1.9859577e-13 | H48: 0.99858037 | I48: 1.0009483 | J48: 0.99858037 | K48: 1.0009483 | M48: X Variable 1 | N48: 0.9979839 | O48: 2.7682457e-05 | P48: 36051.131 | Q48: 7.6941776e-10 | R48: 0.99786479 | S48: 0.99810301 | T48: 0.99786479 | U48: 0.99810301
C50: Resistansi Pembumian Protektif (Ω)
C51: SUMMARY OUTPUT | M51: Arus AC (uA)
M52: SUMMARY OUTPUT
C53: Regression Statistics
...
