Workbook

Sheet input data
C2: LEMBAR KERJA KALIBRASI PHACO EMULSIFIKASI
B4: A. PENDATAAN ADMINISTRASI
B5: No. Sertifikat : | C5: S.431 | E5: No. Alat :
B6: Nama Alat : | C6: Phaco Emulsifikasi | E6: Pemilik : | G6: PT. Bumi Indah Putra
B7: Merek : | C7: MD | E7: Ruangan : | G7: lab
B8: Model/Tipe : | C8: MD-480A | E8: Tgl. Terima : | G8: 46246
B9: No. Seri : | C9: 1213 | E9: Tgl. Kalibrasi : | G9: 46246
B10: Kapasitas : | E10: Petugas Kalibrasi : | G10: el
B11: Resolusi : | C11: 1 | E11: kalibrasi berikutnya: | G11: 46611
B13: B. DAFTAR ALAT YANG DIGUNAKAN
B14: No | C14: Nama Alat | E14: Merk | F14: Type / Model | G14: No. Seri
B15: 1 | C15: Digital Pressure Meter | E15: Netech | F15: Digimano 2500 | G15: 40947
B16: 2 | C16: Electrical Safety Analyzer | E16: Fluke Biomedical | F16: ESA612 | G16: 6579027
B17: 3 | C17: Thermohygrometer | E17: Taffware | F17: HTC-1 | G17: TH-01
B20: C. PENGUKURAN KONDISI LINGKUNGAN
B21: Kondisi Ruang | C21: Awal | D21: Akhir | E21: Toleransi
B22: Suhu (°C) | C22: 25.4 | D22: 25.5 | E22: 25 ± 6 °C
B23: RH (%) | C23: 54 | D23: 55 | E23: 55 % ± 20 %
B24: Tegangan | C24: L-N | D24: 231.5 | E24: ± 10 %Vac
C25: L-G | D25: 88.6 | E25: Vac
C26: N-G | D26: 136.9 | E26: Vac
B29: D. PEMERIKSAAN FISIK DAN FUNGSI ALAT
B30: Bagian Alat | C30: Keterangan | F30: Hasil Pengamatan
B31: Badan Permukaan | C31: periksa bagian luar unit, pastikan bersih, terpasang ketat satu dan lainnya dan tidak ada bekas tertimpa cairan ataupun gangguan lainnya. | F31: 1 | G31: Baik
G33: Tidak baik
B35: Kotak kontak alat | C35: Periksa apakah ada gangguan pada tusuk kontak (AC-Power). Gerak-gerakkan kotak kontak untuk memastikan keamanannya. Goyang-goyangkan kotak kontak untuk memastikan tidak ada baut atau mur yang longgar | F35: 1 | G35: Baik
G37: Tidak baik
B39: Kabel Catu Utama | C39: Periksa kabel, apakah terlihat ada kerusakan atau bagian isolasi yang terkelupas. | F39: 1 | G39: Baik
G40: Tidak baik
B41: Tombol saklar dan kontrol | C41: sebelum mempergunakan/mengubah-ubah tombol kontrol, periksa posisinya, jika terlihat tidak berada pada posisinya (periksa dengan menggunakan mode pemeriksaan standar). Bandingkan dengan posisi control. Ingat peraturan tersebut dan jangan lupa untuk mengembalikan pada setting awal jika sudah selesai menggunakan | F41: 1 | G41: Baik
G43: Tidak baik
B45: Tampilan dan indicator | C45: Selama pengecekan fungsi, pastikan lampu indicator dan tampilan layar berfungsi baik. | F45: 1 | G45: Baik
G46: Tidak baik
B47: Sistem pengunci pergerakan | C47: Lakukan pemeriksaan system pengunci pergerakan | F47: 1 | G47: Baik
G48: Tidak baik
B49: Filter | C49: Periksa kondisi filter pastikan tidak kotor | F49: 1 | G49: Baik
G51: Tidak baik
B54: E. PENGUKURAN KESELAMATAN LISTRIK
B55: Tipe bagian yang diaplikasikan | E55: B | F55: BF | G55: CF
B56: Kelas proteksi | E56: I | F56: II | G56: Baterai
...

Sheet skorsing
C2: Lembar Kerja Phaco Emulsifikasi
B4: A. PENDATAAN ADMINISTRASI
B5: No. Sertifikat : | C5: ='input data'!C5 -> S.431 | G5: No. Alat : | H5: ='input data'!G5 -> 0
B6: Nama Alat : | C6: ='input data'!C6 -> Phaco Emulsifikasi | G6: Pemilik : | H6: ='input data'!G6 -> PT. Bumi Indah Putra
B7: Merek : | C7: ='input data'!C7 -> MD | G7: Ruangan : | H7: ='input data'!G7 -> lab
B8: Model/Tipe : | C8: ='input data'!C8 -> MD-480A | G8: Tgl. Terima : | H8: ='input data'!G8 -> 46246
B9: No. Seri : | C9: ='input data'!C9 -> 1213 | G9: Tgl. Kalibrasi : | H9: ='input data'!G9 -> 46246
B10: Kapasitas : | C10: ='input data'!C10 -> 0 | G10: Petugas Kalibrasi : | H10: ='input data'!G10 -> el
B11: Resolusi : | C11: ='input data'!C11 -> 1
B13: B. DAFTAR ALAT YANG DIGUNAKAN
B14: No | C14: Nama Alat | F14: Merk | G14: Type / Model | H14: No. Seri | J14: 1 | K14: 2 | L14: 3 | M14: 4 | N14: 5 | O14: 6 | P14: 7 | Q14: 8 | R14: 9 | S14: 10 | T14: 11 | U14: 12 | V14: 13 | X14: 13 | Y14: 14
B15: 1 | C15: ='input data'!C15 -> Digital Pressure Meter | F15: ='input data'!E15 -> Netech | G15: ='input data'!F15 -> Digimano 2500 | H15: ='input data'!G15 -> 40947 | J15: No. Seri | K15: No | L15: Nama | M15: Merk | N15: Type | O15: Regresi Suhu | Q15: Regresi Kelembaban | S15: U95 | U15: mean terkoreksi | W15: tgl kalibrasi
B16: 3 | C16: ='input data'!C16 -> Electrical Safety Analyzer | F16: ='input data'!E16 -> Fluke Biomedical | G16: ='input data'!F16 -> ESA612 | H16: ='input data'!G16 -> 6579027 | O16: Intercept | P16: X variabel | Q16: Intercept | R16: X variabel | S16: Suhu | T16: Kelembaban | U16: suhu | V16: kelembaban
B17: 4 | C17: ='input data'!C17 -> Thermohygrometer | F17: ='input data'!E17 -> Taffware | G17: ='input data'!F17 -> HTC-1 | H17: ='input data'!G17 -> TH-01 | J17: =[1]ARRAY!D6 -> TH-01 | K17: =[1]ARRAY!E6 -> 1 | L17: =[1]ARRAY!F6 -> Digital thermohygrometer | M17: =[1]ARRAY!G6 -> Taffware | N17: =[1]ARRAY!H6 -> HTC-1 | O17: =[1]ARRAY!I6 -> -0.35317479 | P17: =[1]ARRAY!J6 -> 1.0389536 | Q17: =[1]ARRAY!K6 -> -19.598182 | ... T17: =[1]ARRAY!N6 -> 2.7 | U17: =O17+P17*$F$22 -> 26.088195 | V17: =Q17+R17*$F$23 -> 55.691091 | W17: =[2]ARRAY!$O$6 -> 45799
J18: =[1]ARRAY!D7 -> TH-02 | K18: =[1]ARRAY!E7 -> 2 | L18: =[1]ARRAY!F7 -> Digital thermohygrometer | M18: =[1]ARRAY!G7 -> Taffware | N18: =[1]ARRAY!H7 -> HTC-1 | O18: =[1]ARRAY!I7 -> -0.036218787 | P18: =[1]ARRAY!J7 -> 1.023044 | Q18: =[1]ARRAY!K7 -> -20.981818 | ... T18: =[1]ARRAY!N7 -> 3.1 | U18: =O18+P18*$F$22 -> 26.000251 | V18: =Q18+R18*$F$23 -> 51.453636 | W18: =[2]ARRAY!$O$6 -> 45799
J19: =[1]ARRAY!D8 -> TH-03 | K19: =[1]ARRAY!E8 -> 3 | L19: =[1]ARRAY!F8 -> Digital thermohygrometer | M19: =[1]ARRAY!G8 -> Taffware | N19: =[1]ARRAY!H8 -> HTC-1 | O19: =[1]ARRAY!I8 -> -0.40318668 | P19: =[1]ARRAY!J8 -> 1.0430321 | Q19: =[1]ARRAY!K8 -> -19.666364 | ... T19: =[1]ARRAY!N8 -> 2.7 | U19: =O19+P19*$F$22 -> 26.14198 | V19: =Q19+R19*$F$23 -> 51.609727 | W19: =[2]ARRAY!$O$6 -> 45799
B20: C. PENGUKURAN KONDISI LINGKUNGAN | J20: =[1]ARRAY!D9 -> TH-04 | K20: =[1]ARRAY!E9 -> 4 | L20: =[1]ARRAY!F9 -> Digital thermohygrometer | M20: =[1]ARRAY!G9 -> Taffware | N20: =[1]ARRAY!H9 -> HTC-1 | O20: =[1]ARRAY!I9 -> 0.19985731 | P20: =[1]ARRAY!J9 -> 0.99894174 | Q20: =[1]ARRAY!K9 -> -20.05 | ... T20: =[1]ARRAY!N9 -> 2.9 | U20: =O20+P20*$F$22 -> 25.622924 | V20: =Q20+R20*$F$23 -> 51.840455 | W20: =[2]ARRAY!$O$6 -> 45799
B21: Kondisi Ruang | C21: Awal | D21: Akhir | E21: Toleransi | F21: mean | G21: mean terkoreksi | H21: ktps
B22: Suhu (°C) | C22: ='input data'!C22 -> 25.4 | D22: ='input data'!D22 -> 25.5 | E22: 25 ± 6 °C | F22: =AVERAGE(C22:D22) -> 25.45 | G22: =VLOOKUP(H17,J17:V20,12,FALSE) -> 26.088195 | H22: =VLOOKUP(H17,J17:V20,10,FALSE) -> 0.5
B23: RH (%) | C23: ='input data'!C23 -> 54 | D23: ='input data'!D23 -> 55 | E23: 50 % ± 20 % | F23: =AVERAGE(C23:D23) -> 54.5 | G23: =VLOOKUP(H17,J17:V20,13,FALSE) -> 55.691091 | H23: =VLOOKUP(H17,J17:V20,11,FALSE) -> 2.7
B24: Tegangan | C24: L-N | D24: ='input data'!D24 -> 231.5 | E24: ± 10 %Vac | G24: =VLOOKUP(H16,N47:AC47,7,FALSE)+VLOOKUP(H16,N47:AC47,8,FALSE)*D24 -> 231.63429
C25: L-G | D25: ='input data'!D25 -> 88.6 | E25: Vac | G25: =D25 -> 88.6
C26: N-G | D26: ='input data'!D26 -> 136.9 | E26: Vac | G26: =D26 -> 136.9
B29: D. PEMERIKSAAN FISIK DAN FUNGSI ALAT
B30: Bagian Alat | C30: Keterangan | H30: Hasil Pengamatan | J30: Hasil | K30: Bobot | L30: Score
B31: ='input data'!B31:B34 -> Badan Permukaan | C31: ='input data'!C31:E34 -> periksa bagian luar unit, pastikan bersih, terpasang ketat satu dan lainnya dan tidak ada bekas tertimpa cairan ataupun gangguan lainnya. | H31: ='input data'!F31 -> 1 | I31: Baik | J31: =IF(H31=1,"LULUS","TIDAK LULUS") -> LULUS | K31: =(COUNTIF(J31:J50,"LULUS")/(COUNTA(J31:J50))*100%) -> 1 | L31: =IF(K31<=70%,0,10) -> 10
I33: Tidak baik
B35: ='input data'!B35:B38 -> Kotak kontak alat | C35: ='input data'!C35:E38 -> Periksa apakah ada gangguan pada tusuk kontak (AC-Power). Gerak-gerakkan kotak kontak untuk memastikan keamanannya. Goyang-goyangkan kotak kontak untuk memastikan tidak ada baut atau mur yang longgar | H35: ='input data'!F35:F38 -> 1 | I35: Baik | J35: =IF(H35=1,"LULUS","TIDAK LULUS") -> LULUS
I37: Tidak baik
B39: ='input data'!B39:B40 -> Kabel Catu Utama | C39: ='input data'!C39:E40 -> Periksa kabel, apakah terlihat ada kerusakan atau bagian isolasi yang terkelupas. | H39: ='input data'!F39:F40 -> 1 | I39: Baik | J39: =IF(H39=1,"LULUS","TIDAK LULUS") -> LULUS
I40: Tidak baik
B41: ='input data'!B41:B42 -> Tombol saklar dan kontrol | C41: ='input data'!C41:E44 -> sebelum mempergunakan/mengubah-ubah tombol kontrol, periksa posisinya, jika terlihat tidak berada pada posisinya (periksa dengan menggunakan mode pemeriksaan standar). Bandingkan dengan posisi control. Ingat peraturan tersebut dan jangan lupa untuk mengembalikan pada setting awal jika sudah selesai menggunakan | H41: ='input data'!F41:F44 -> 1 | I41: Baik | J41: =IF(H41=1,"LULUS","TIDAK LULUS") -> LULUS
I43: Tidak baik
N44: 1 | O44: 2 | P44: 3 | Q44: 4 | R44: 5 | S44: 6 | T44: 7 | V44: 8 | W44: 9 | X44: 10 | Y44: 11 | AA44: 12 | AB44: 13 | AC44: 14 | AD44: 15 | AE44: 16
B45: ='input data'!B45:B46 -> Tampilan dan indicator | C45: ='input data'!C45:E46 -> Selama pengecekan fungsi, pastikan lampu indicator dan tampilan layar berfungsi baik. | H45: ='input data'!F45:F46 -> 1 | I45: Baik | J45: =IF(H45=1,"LULUS","TIDAK LULUS") -> LULUS | N45: No. Seri | O45: No | P45: Merk | Q45: Type | R45: Tanggal Kalibrasi | S45: Tertelusur | T45: Tegangan | W45: Arus DC (µA) | Y45: Arus AC (µA) | AB45: Resistansi Pembumian (Ω) | AD45: Resistansi Isolasi (MΩ)
I46: Tidak baik | T46: Intercept | U46: Variabel X | V46: Intercept | W46: Variabel X | X46: Intercept | Y46: Variabel X | Z46: Intercept | AA46: Variabel X | AB46: Intercept | AC46: Variabel X | AD46: Intercept | AE46: Variabel X
B47: ='input data'!B47:B48 -> Sistem pengunci pergerakan | C47: ='input data'!C47:E48 -> Lakukan pemeriksaan system pengunci pergerakan | H47: ='input data'!F47:F48 -> 1 | I47: Baik | J47: =IF(H47=1,"LULUS","TIDAK LULUS") -> LULUS | N47: =[3]ARRAY!C7 -> 6579027 | O47: =[3]ARRAY!D7 -> 1 | P47: =[3]ARRAY!E7 -> Fluke Biomedical | Q47: =[3]ARRAY!F7 -> ESA16 | R47: =[3]ARRAY!G7 -> 45819 | S47: =[3]ARRAY!H7 -> LK-110-IDN | T47: =[3]ARRAY!I7 -> 0.18884844 | U47: =[3]ARRAY!J7 -> 0.99976434 | ... AE47: =[3]ARRAY!T7 -> 0
I48: Tidak baik
B49: ='input data'!B49:B52 -> Filter | C49: ='input data'!C49:E52 -> Periksa kondisi filter pastikan tidak kotor | H49: ='input data'!F49:F52 -> 1 | I49: Baik | J49: =IF(H49=1,"LULUS","TIDAK LULUS") -> LULUS
I50: Tidak baik
...

Sheet standar
J9: 0.0024 | K9: mbar= | L9: 0.0018 | M9: mmhg

Sheet budget
B1: NAIK | O1: TURUN
B3: =skorsing!G88 -> 37.503 | O3: =B3 -> 37.503
B4: Komponen | C4: satuan | D4: Distribusi | E4: U | F4: Pembagi | G4: v | H4: u | I4: c | J4: (u.c) | K4: (u.c)² | L4: (u.c)⁴/v | O4: Komponen | P4: satuan | Q4: Distribusi | R4: U | S4: Pembagi | T4: v | U4: u | V4: c | W4: (u.c) | X4: (u.c)² | Y4: (u.c)⁴/v
B5: Pengukuran berulang | C5: mmHg | D5: t-student | E5: =skorsing!S106 -> 0 | F5: 1 | G5: =3-1 -> 2 | H5: =E5/F5 -> 0 | I5: 1 | J5: =H5*I5 -> 0 | K5: =J5^2 -> 0 | L5: =J5^4/G5 -> 0 | O5: Pengukuran berulang | P5: mmHg | Q5: t-student | R5: =skorsing!T106 -> 0.075006 | S5: 1 | T5: =3-1 -> 2 | U5: =R5/S5 -> 0.075006 | V5: 1 | W5: =U5*V5 -> 0.075006 | X5: =W5^2 -> 0.0056259 | Y5: =W5^4/T5 -> 1.5825376e-05
B6: Sertifikat standar | C6: mmHg | D6: Normal | E6: =standar!$L$9*budget!B3 -> 0.0675054 | F6: 2 | G6: =1/2*(100/10)^2 -> 50 | H6: =E6/F6 -> 0.0337527 | I6: 1 | J6: =H6*I6 -> 0.0337527 | K6: =J6^2 -> 0.0011392448 | L6: =J6^4/G6 -> 2.5957572e-08 | O6: Sertifikat standar | P6: mmHg | Q6: Normal | R6: =standar!$L$9*budget!O3 -> 0.0675054 | S6: 2 | T6: =1/2*(100/10)^2 -> 50 | U6: =R6/S6 -> 0.0337527 | V6: 1 | W6: =U6*V6 -> 0.0337527 | X6: =W6^2 -> 0.0011392448 | Y6: =W6^4/T6 -> 2.5957572e-08
B7: Resolusi | C7: mmHg | D7: Rectangular | E7: =0.5*'input data'!$C$11 -> 0.5 | F7: =SQRT(3) -> 1.7320508 | G7: =1/2*(100/10)^2 -> 50 | H7: =E7/F7 -> 0.28867513 | I7: 1 | J7: =H7*I7 -> 0.28867513 | K7: =J7^2 -> 0.083333333 | L7: =J7^4/G7 -> 0.00013888889 | O7: Resolusi | P7: mmHg | Q7: Rectangular | R7: =0.5*'input data'!$C$11 -> 0.5 | S7: =SQRT(3) -> 1.7320508 | T7: =1/2*(100/10)^2 -> 50 | U7: =R7/S7 -> 0.28867513 | V7: 1 | W7: =U7*V7 -> 0.28867513 | X7: =W7^2 -> 0.083333333 | Y7: =W7^4/T7 -> 0.00013888889
B8: Drift | C8: mmHg | D8: Rectangular | E8: =1/2*10%*(0.1%*B3) -> 0.00187515 | F8: =SQRT(3) -> 1.7320508 | G8: =1/2*(100/10)^2 -> 50 | H8: =E8/F8 -> 0.0010826184 | I8: 1 | J8: =H8*I8 -> 0.0010826184 | K8: =J8^2 -> 1.1720625e-06 | L8: =J8^4/G8 -> 2.747461e-14 | O8: Drift | P8: mmHg | Q8: Rectangular | R8: =1/2*10%*(0.1%*O3) -> 0.00187515 | S8: =SQRT(3) -> 1.7320508 | T8: =1/2*(100/10)^2 -> 50 | U8: =R8/S8 -> 0.0010826184 | V8: 1 | W8: =U8*V8 -> 0.0010826184 | X8: =W8^2 -> 1.1720625e-06 | Y8: =W8^4/T8 -> 2.747461e-14
B9: Jumlah | K9: =SUM(K5:K8) -> 0.08447375 | L9: =SUM(L5:L8) -> 0.00013891485 | O9: Jumlah | X9: =SUM(X5:X8) -> 0.09009965 | Y9: =SUM(Y5:Y8) -> 0.00015474022
B10: Ketidakpastian baku gabungan, Uc | K10: =SQRT(K9) -> 0.29064368 | O10: Ketidakpastian baku gabungan, Uc | X10: =SQRT(X9) -> 0.30016604
B11: Derajat kebebasan effektif, V eff | K11: =K10^4/L9 -> 51.368264 | O11: Derajat kebebasan effektif, V eff | X11: =X10^4/Y9 -> 52.461777
B12: Faktor cakupan, k-student untuk Veff dan CL 95% | K12: =TINV(0.05,K11) -> 2.0075838 | O12: Faktor cakupan, k-student untuk Veff dan CL 95% | X12: =TINV(0.05,X11) -> 2.0066468
B13: Ketidakpastian bentangan, U=k.Uc | K13: =K12*K10 -> 0.58349154 | O13: Ketidakpastian bentangan, U=k.Uc | X13: =X12*X10 -> 0.60232722
B15: =skorsing!G89 -> 75.006 | O15: =B15 -> 75.006
B16: Komponen | C16: satuan | D16: Distribusi | E16: U | F16: Pembagi | G16: v | H16: u | I16: c | J16: (u.c) | K16: (u.c)² | L16: (u.c)⁴/v | O16: Komponen | P16: satuan | Q16: Distribusi | R16: U | S16: Pembagi | T16: v | U16: u | V16: c | W16: (u.c) | X16: (u.c)² | Y16: (u.c)⁴/v
B17: Pengukuran berulang | C17: mmHg | D17: t-student | E17: =skorsing!S107 -> 0 | F17: 1 | G17: =3-1 -> 2 | H17: =E17/F17 -> 0 | I17: 1 | J17: =H17*I17 -> 0 | K17: =J17^2 -> 0 | L17: =J17^4/G17 -> 0 | O17: Pengukuran berulang | P17: mmHg | Q17: t-student | R17: =skorsing!T107 -> 0.075006 | S17: 1 | T17: =3-1 -> 2 | U17: =R17/S17 -> 0.075006 | V17: 1 | W17: =U17*V17 -> 0.075006 | X17: =W17^2 -> 0.0056259 | Y17: =W17^4/T17 -> 1.5825376e-05
B18: Sertifikat standar | C18: mmHg | D18: Normal | E18: =standar!$L$9*budget!B15 -> 0.1350108 | F18: 2 | G18: =1/2*(100/10)^2 -> 50 | H18: =E18/F18 -> 0.0675054 | I18: 1 | J18: =H18*I18 -> 0.0675054 | K18: =J18^2 -> 0.004556979 | L18: =J18^4/G18 -> 4.1532116e-07 | O18: Sertifikat standar | P18: mmHg | Q18: Normal | R18: =standar!$L$9*budget!O15 -> 0.1350108 | S18: 2 | T18: =1/2*(100/10)^2 -> 50 | U18: =R18/S18 -> 0.0675054 | V18: 1 | W18: =U18*V18 -> 0.0675054 | X18: =W18^2 -> 0.004556979 | Y18: =W18^4/T18 -> 4.1532116e-07
B19: Resolusi | C19: mmHg | D19: Rectangular | E19: =0.5*'input data'!$C$11 -> 0.5 | F19: =SQRT(3) -> 1.7320508 | G19: =1/2*(100/10)^2 -> 50 | H19: =E19/F19 -> 0.28867513 | I19: 1 | J19: =H19*I19 -> 0.28867513 | K19: =J19^2 -> 0.083333333 | L19: =J19^4/G19 -> 0.00013888889 | O19: Resolusi | P19: mmHg | Q19: Rectangular | R19: =0.5*'input data'!$C$11 -> 0.5 | S19: =SQRT(3) -> 1.7320508 | T19: =1/2*(100/10)^2 -> 50 | U19: =R19/S19 -> 0.28867513 | V19: 1 | W19: =U19*V19 -> 0.28867513 | X19: =W19^2 -> 0.083333333 | Y19: =W19^4/T19 -> 0.00013888889
B20: Drift | C20: mmHg | D20: Rectangular | E20: =1/2*10%*(0.1%*B15) -> 0.0037503 | F20: =SQRT(3) -> 1.7320508 | G20: =1/2*(100/10)^2 -> 50 | H20: =E20/F20 -> 0.0021652367 | I20: 1 | J20: =H20*I20 -> 0.0021652367 | K20: =J20^2 -> 4.68825e-06 | L20: =J20^4/G20 -> 4.3959377e-13 | O20: Drift | P20: mmHg | Q20: Rectangular | R20: =1/2*10%*(0.1%*O15) -> 0.0037503 | S20: =SQRT(3) -> 1.7320508 | T20: =1/2*(100/10)^2 -> 50 | U20: =R20/S20 -> 0.0021652367 | V20: 1 | W20: =U20*V20 -> 0.0021652367 | X20: =W20^2 -> 4.68825e-06 | Y20: =W20^4/T20 -> 4.3959377e-13
B21: Jumlah | K21: =SUM(K17:K20) -> 0.087895001 | L21: =SUM(L17:L20) -> 0.00013930421 | O21: Jumlah | X21: =SUM(X17:X20) -> 0.093520901 | Y21: =SUM(Y17:Y20) -> 0.00015512959
B22: Ketidakpastian baku gabungan, Uc | K22: =SQRT(K21) -> 0.29647091 | O22: Ketidakpastian baku gabungan, Uc | X22: =SQRT(X21) -> 0.30581187
B23: Derajat kebebasan effektif, V eff | K23: =K22^4/L21 -> 55.457987 | O23: Derajat kebebasan effektif, V eff | X23: =X22^4/Y21 -> 56.379696
B24: Faktor cakupan, k-student untuk Veff dan CL 95% | K24: =TINV(0.05,K23) -> 2.0040448 | O24: Faktor cakupan, k-student untuk Veff dan CL 95% | X24: =TINV(0.05,X23) -> 2.0032407
B25: Ketidakpastian bentangan, U=k.Uc | K25: =K24*K22 -> 0.59414098 | O25: Ketidakpastian bentangan, U=k.Uc | X25: =X24*X22 -> 0.61261479
B27: =skorsing!G90 -> 112.509 | O27: =B27 -> 112.509
B28: Komponen | C28: satuan | D28: Distribusi | E28: U | F28: Pembagi | G28: v | H28: u | I28: c | J28: (u.c) | K28: (u.c)² | L28: (u.c)⁴/v | O28: Komponen | P28: satuan | Q28: Distribusi | R28: U | S28: Pembagi | T28: v | U28: u | V28: c | W28: (u.c) | X28: (u.c)² | Y28: (u.c)⁴/v
B29: Pengukuran berulang | C29: mmHg | D29: t-student | E29: =skorsing!S108 -> 0.050004 | F29: 1 | G29: =3-1 -> 2 | H29: =E29/F29 -> 0.050004 | I29: 1 | J29: =H29*I29 -> 0.050004 | K29: =J29^2 -> 0.0025004 | L29: =J29^4/G29 -> 3.1260001e-06 | O29: Pengukuran berulang | P29: mmHg | Q29: t-student | R29: =skorsing!T108 -> 0 | S29: 1 | T29: =3-1 -> 2 | U29: =R29/S29 -> 0 | V29: 1 | W29: =U29*V29 -> 0 | X29: =W29^2 -> 0 | Y29: =W29^4/T29 -> 0
B30: Sertifikat standar | C30: mmHg | D30: Normal | E30: =standar!$L$9*budget!B27 -> 0.2025162 | F30: 2 | G30: =1/2*(100/10)^2 -> 50 | H30: =E30/F30 -> 0.1012581 | I30: 1 | J30: =H30*I30 -> 0.1012581 | K30: =J30^2 -> 0.010253203 | L30: =J30^4/G30 -> 2.1025634e-06 | O30: Sertifikat standar | P30: mmHg | Q30: Normal | R30: =standar!$L$9*budget!O27 -> 0.2025162 | S30: 2 | T30: =1/2*(100/10)^2 -> 50 | U30: =R30/S30 -> 0.1012581 | V30: 1 | W30: =U30*V30 -> 0.1012581 | X30: =W30^2 -> 0.010253203 | Y30: =W30^4/T30 -> 2.1025634e-06
B31: Resolusi | C31: mmHg | D31: Rectangular | E31: =0.5*'input data'!$C$11 -> 0.5 | F31: =SQRT(3) -> 1.7320508 | G31: =1/2*(100/10)^2 -> 50 | H31: =E31/F31 -> 0.28867513 | I31: 1 | J31: =H31*I31 -> 0.28867513 | K31: =J31^2 -> 0.083333333 | L31: =J31^4/G31 -> 0.00013888889 | O31: Resolusi | P31: mmHg | Q31: Rectangular | R31: =0.5*'input data'!$C$11 -> 0.5 | S31: =SQRT(3) -> 1.7320508 | T31: =1/2*(100/10)^2 -> 50 | U31: =R31/S31 -> 0.28867513 | V31: 1 | W31: =U31*V31 -> 0.28867513 | X31: =W31^2 -> 0.083333333 | Y31: =W31^4/T31 -> 0.00013888889
B32: Drift | C32: mmHg | D32: Rectangular | E32: =1/2*10%*(0.1%*B27) -> 0.00562545 | F32: =SQRT(3) -> 1.7320508 | G32: =1/2*(100/10)^2 -> 50 | H32: =E32/F32 -> 0.0032478551 | I32: 1 | J32: =H32*I32 -> 0.0032478551 | K32: =J32^2 -> 1.0548563e-05 | L32: =J32^4/G32 -> 2.2254434e-12 | O32: Drift | P32: mmHg | Q32: Rectangular | R32: =1/2*10%*(0.1%*O27) -> 0.00562545 | S32: =SQRT(3) -> 1.7320508 | T32: =1/2*(100/10)^2 -> 50 | U32: =R32/S32 -> 0.0032478551 | V32: 1 | W32: =U32*V32 -> 0.0032478551 | X32: =W32^2 -> 1.0548563e-05 | Y32: =W32^4/T32 -> 2.2254434e-12
B33: Jumlah | K33: =SUM(K29:K32) -> 0.096097485 | L33: =SUM(L29:L32) -> 0.00014411745 | O33: Jumlah | X33: =SUM(X29:X32) -> 0.093597085 | Y33: =SUM(Y29:Y32) -> 0.00014099145
B34: Ketidakpastian baku gabungan, Uc | K34: =SQRT(K33) -> 0.30999594 | O34: Ketidakpastian baku gabungan, Uc | X34: =SQRT(X33) -> 0.30593641
B35: Derajat kebebasan effektif, V eff | K35: =K34^4/L33 -> 64.07778 | O35: Derajat kebebasan effektif, V eff | X35: =X34^4/Y33 -> 62.134363
B36: Faktor cakupan, k-student untuk Veff dan CL 95% | K36: =TINV(0.05,K35) -> 1.9977297 | O36: Faktor cakupan, k-student untuk Veff dan CL 95% | X36: =TINV(0.05,X35) -> 1.9989715
B37: Ketidakpastian bentangan, U=k.Uc | K37: =K36*K34 -> 0.61928809 | O37: Ketidakpastian bentangan, U=k.Uc | X37: =X36*X34 -> 0.61155816
B39: =skorsing!G91 -> 150.012 | O39: =B39 -> 150.012
B40: Komponen | C40: satuan | D40: Distribusi | E40: U | F40: Pembagi | G40: v | H40: u | I40: c | J40: (u.c) | K40: (u.c)² | L40: (u.c)⁴/v | O40: Komponen | P40: satuan | Q40: Distribusi | R40: U | S40: Pembagi | T40: v | U40: u | V40: c | W40: (u.c) | X40: (u.c)² | Y40: (u.c)⁴/v
B41: Pengukuran berulang | C41: mmHg | D41: t-student | E41: =skorsing!S109 -> 0 | F41: 1 | G41: =3-1 -> 2 | H41: =E41/F41 -> 0 | I41: 1 | J41: =H41*I41 -> 0 | K41: =J41^2 -> 0 | L41: =J41^4/G41 -> 0 | O41: Pengukuran berulang | P41: mmHg | Q41: t-student | R41: =skorsing!T109 -> 0.025002 | S41: 1 | T41: =3-1 -> 2 | U41: =R41/S41 -> 0.025002 | V41: 1 | W41: =U41*V41 -> 0.025002 | X41: =W41^2 -> 0.0006251 | Y41: =W41^4/T41 -> 1.9537501e-07
B42: Sertifikat standar | C42: mmHg | D42: Normal | E42: =standar!$L$9*budget!B39 -> 0.2700216 | F42: 2 | G42: =1/2*(100/10)^2 -> 50 | H42: =E42/F42 -> 0.1350108 | I42: 1 | J42: =H42*I42 -> 0.1350108 | K42: =J42^2 -> 0.018227916 | L42: =J42^4/G42 -> 6.6451385e-06 | O42: Sertifikat standar | P42: mmHg | Q42: Normal | R42: =standar!$L$9*budget!O39 -> 0.2700216 | S42: 2 | T42: =1/2*(100/10)^2 -> 50 | U42: =R42/S42 -> 0.1350108 | V42: 1 | W42: =U42*V42 -> 0.1350108 | X42: =W42^2 -> 0.018227916 | Y42: =W42^4/T42 -> 6.6451385e-06
B43: Resolusi | C43: mmHg | D43: Rectangular | E43: =0.5*'input data'!$C$11 -> 0.5 | F43: =SQRT(3) -> 1.7320508 | G43: =1/2*(100/10)^2 -> 50 | H43: =E43/F43 -> 0.28867513 | I43: 1 | J43: =H43*I43 -> 0.28867513 | K43: =J43^2 -> 0.083333333 | L43: =J43^4/G43 -> 0.00013888889 | O43: Resolusi | P43: mmHg | Q43: Rectangular | R43: =0.5*'input data'!$C$11 -> 0.5 | S43: =SQRT(3) -> 1.7320508 | T43: =1/2*(100/10)^2 -> 50 | U43: =R43/S43 -> 0.28867513 | V43: 1 | W43: =U43*V43 -> 0.28867513 | X43: =W43^2 -> 0.083333333 | Y43: =W43^4/T43 -> 0.00013888889
B44: Drift | C44: mmHg | D44: Rectangular | E44: =1/2*10%*(0.1%*B39) -> 0.0075006 | F44: =SQRT(3) -> 1.7320508 | G44: =1/2*(100/10)^2 -> 50 | H44: =E44/F44 -> 0.0043304734 | I44: 1 | J44: =H44*I44 -> 0.0043304734 | K44: =J44^2 -> 1.8753e-05 | L44: =J44^4/G44 -> 7.0335003e-12 | O44: Drift | P44: mmHg | Q44: Rectangular | R44: =1/2*10%*(0.1%*O39) -> 0.0075006 | S44: =SQRT(3) -> 1.7320508 | T44: =1/2*(100/10)^2 -> 50 | U44: =R44/S44 -> 0.0043304734 | V44: 1 | W44: =U44*V44 -> 0.0043304734 | X44: =W44^2 -> 1.8753e-05 | Y44: =W44^4/T44 -> 7.0335003e-12
...

Sheet Laporan
C2: LEMBAR KERJA KALIBRASI PHACO EMULSIFIKASI
B4: A. PENDATAAN ADMINISTRASI
C5: Nama Pelanggan : | D5: =skorsing!H6 -> PT. Bumi Indah Putra | E5: Resolusi : | F5: =skorsing!C11 -> 1
C6: Nama Alat : | D6: =skorsing!C6 -> Phaco Emulsifikasi | E6: Rentang Ukur :
E7: Ruangan Tempat Alat : | F7: =skorsing!H7 -> lab
C8: Merek : | D8: =skorsing!C7 -> MD | E8: Tgl. Terima | F8: =skorsing!H8 -> 46246
C9: Model/Tipe : | D9: =skorsing!C8 -> MD-480A | E9: Tgl. Kalibrasi | F9: =skorsing!H9 -> 46246
C10: No. Seri : | D10: =skorsing!C9 -> 1213 | E10: Nama Petugas Kalibrasi : | F10: =skorsing!H10 -> el
B13: B. DAFTAR ALAT YANG DIGUNAKAN
B14: No | C14: Nama Alat | E14: Merk | F14: Tipe / Model | G14: No. Seri
B15: 1 | C15: =skorsing!C15 -> Digital Pressure Meter | E15: =skorsing!F15 -> Netech | F15: =skorsing!G15 -> Digimano 2500 | G15: =skorsing!H15 -> 40947
B16: 2 | C16: =skorsing!C16 -> Electrical Safety Analyzer | E16: =skorsing!F16 -> Fluke Biomedical | F16: =skorsing!G16 -> ESA612 | G16: =skorsing!H16 -> 6579027
B17: 3 | C17: =skorsing!C17 -> Thermohygrometer | E17: =skorsing!F17 -> Taffware | F17: =skorsing!G17 -> HTC-1 | G17: =skorsing!H17 -> TH-01
B20: C. PENGUKURAN KONDISI LINGKUNGAN
C21: Kondisi Ruang | D21: terkoreksi | E21: ktps
C22: Suhu (°C) | D22: =skorsing!G22 -> 26.088195 | E22: =skorsing!H22 -> 0.5
C23: RH (%) | D23: =skorsing!G23 -> 55.691091 | E23: =skorsing!H23 -> 2.7
C24: =[5]skorsing!B24 -> Tegangan | D24: =skorsing!G24 -> 231.63429
B26: D. PEMERIKSAAN FISIK DAN FUNGSI ALAT
C27: Bagian Alat | D27: Keterangan | G27: Hasil Pengamatan
C28: =skorsing!B31 -> Badan Permukaan | D28: =skorsing!C31 -> periksa bagian luar unit, pastikan bersih, terpasang ketat satu dan lainnya dan tidak ada bekas tertimpa cairan ataupun gangguan lainnya. | G28: =IF(skorsing!H31=1,"BAIK","TIDAK BAIK") -> BAIK
C30: =skorsing!B35 -> Kotak kontak alat | D30: =skorsing!C35 -> Periksa apakah ada gangguan pada tusuk kontak (AC-Power). Gerak-gerakkan kotak kontak untuk memastikan keamanannya. Goyang-goyangkan kotak kontak untuk memastikan tidak ada baut atau mur yang longgar | G30: =IF(skorsing!H35=1,"BAIK","TIDAK BAIK") -> BAIK
C32: =skorsing!B39 -> Kabel Catu Utama | D32: =skorsing!C39 -> Periksa kabel, apakah terlihat ada kerusakan atau bagian isolasi yang terkelupas. | G32: =IF(skorsing!H39=1,"BAIK","TIDAK BAIK") -> BAIK
C34: =skorsing!B41 -> Tombol saklar dan kontrol | D34: =skorsing!C41 -> sebelum mempergunakan/mengubah-ubah tombol kontrol, periksa posisinya, jika terlihat tidak berada pada posisinya (periksa dengan menggunakan mode pemeriksaan standar). Bandingkan dengan posisi control. Ingat peraturan tersebut dan jangan lupa untuk mengembalikan pada setting awal jika sudah selesai menggunakan | G34: =IF(skorsing!H41=1,"BAIK","TIDAK BAIK") -> BAIK
C36: =skorsing!B45 -> Tampilan dan indicator | D36: =skorsing!C45 -> Selama pengecekan fungsi, pastikan lampu indicator dan tampilan layar berfungsi baik. | G36: =IF(skorsing!H45=1,"BAIK","TIDAK BAIK") -> BAIK
C38: =skorsing!B47 -> Sistem pengunci pergerakan | D38: =skorsing!C47 -> Lakukan pemeriksaan system pengunci pergerakan | G38: =IF(skorsing!H47=1,"BAIK","TIDAK BAIK") -> BAIK
C40: =skorsing!B49 -> Filter | D40: =skorsing!C49 -> Periksa kondisi filter pastikan tidak kotor | G40: =IF(skorsing!H49=1,"BAIK","TIDAK BAIK") -> BAIK
B43: E. PENGUKURAN KESELAMATAN LISTRIK
B44: No. | C44: Parameter | D44: Terukur Koreksi | E44: Memenuhi
E45: Ya | F45: Tidak
B46: 1 | C46: =[5]skorsing!C58 -> Resistansi pembumian protektif (Ω) | D46: =skorsing!I63 -> 0.21563072 | E46: =[5]skorsing!J58 -> √
B48: 2 | C48: =[5]skorsing!C59 -> Resistansi Isolasi (MΩ) | D48: =skorsing!I64 -> OR | E48: =[5]skorsing!J59 -> √
B50: 3 | C50: =[5]skorsing!C60 -> Arus bocor peralatan (µA) | D50: =skorsing!I65 -> 0.11128338 | E50: =[5]skorsing!J60 -> √
B54: F. PENGUKURAN KINERJA ALAT
C55: 1. Kalibrasi daya hisap
C56: Setting UUT | D56: pembacaan standar | F56: Koreksi | H56: U95 | K56: SCORE KINERJA ALAT | M56: TOTAL SCORE
D58: naik | E58: turun | F58: naik | G58: turun | H58: naik | I58: turun | K58: =IF(skorsing!AD106>=100,50,0) -> 50 | M58: =K58+skorsing!P63+skorsing!L31 -> 100
C59: =skorsing!B106 -> 37.503 | D59: =skorsing!O106 -> 38.328066 | E59: =skorsing!P106 -> 38.403072 | F59: =skorsing!U106 -> 0.825066 | G59: =skorsing!V106 -> 0.900072 | H59: =skorsing!W106 -> 0.58349154 | I59: =skorsing!X106 -> 0.60232722
C60: =skorsing!B107 -> 75.006 | D60: =skorsing!O107 -> 76.806144 | E60: =skorsing!P107 -> 76.731138 | F60: =skorsing!U107 -> 1.800144 | G60: =skorsing!V107 -> 1.725138 | H60: =skorsing!W107 -> 0.59414098 | I60: =skorsing!X107 -> 0.61261479
C61: =skorsing!B108 -> 112.509 | D61: =skorsing!O108 -> 114.25914 | E61: =skorsing!P108 -> 114.30914 | F61: =skorsing!U108 -> 1.75014 | G61: =skorsing!V108 -> 1.800144 | H61: =skorsing!W108 -> 0.61928809 | I61: =skorsing!X108 -> 0.61155816
...

Sheet Cover
L8: Nomor Sertifikat | P8: : | Q8: =skorsing!C5 -> S.431
L9: Certificate Number
A11: SERTIFIKAT KALIBRASI
A12: Calibration Certificate
B13: DATA ALAT
B14: Instrument ID
C15: Nama Alat | F15: : | G15: =skorsing!C6 -> Phaco Emulsifikasi
C16: Device Name
C17: Merk | F17: : | G17: =skorsing!C7 -> MD
C18: Brand
C19: Type/Model | F19: : | G19: =skorsing!C8 -> MD-480A
C20: Type/Model
C21: Nomor Seri | F21: : | G21: =skorsing!C9 -> 1213
C22: Serial Number
C23: Resolusi | F23: : | G23: =skorsing!C11 -> 1 | H23: ='input data'!C70 -> kPa
C24: Resolution
B26: IDENTITAS PELANGGAN
B27: Customer ID
C28: Pelanggan | F28: : | G28: =skorsing!H6 -> PT. Bumi Indah Putra
C29: Customer
C30: Alamat | F30: : | G30: Jl. Cipendawa Baru, RT.003/RW.002,
C31: Address | G31: Bantargebang, Kec. Bantar Gebang, Kota Bks, Jawa Barat 17151
I33: Sertifikat ini terdiri dari | N33: : | O33: 5 halaman
I34: This certificate consist of
I35: Diterbitkan tanggal | N35: :
I36: Published date
K38: PT. Presisi Kalibrasi Medika
K42: Samsurizal
K43: Direktur
K44: Director

Sheet Laporan Print
L8: Nomor Sertifikat | P8: : | Q8: =Cover!Q8 -> S.431
L9: Certificate Number
A12: LAPORAN KALIBRASI
A13: Calibration Report
A14: =Cover!G15 -> Phaco Emulsifikasi
A16: A. | B16: PENDATAAN ADMINISTRASI
B17: Administration
B18: Merk | I18: : | J18: =Cover!G17 -> MD
B19: Brand
B20: Type/Model | I20: : | J20: =Cover!G19 -> MD-480A
B21: Type/Model
B22: Nomor Seri | I22: : | J22: =Cover!G21 -> 1213
B23: Serial Number
B24: Resolusi | I24: : | J24: =Cover!G23 -> 1 | K24: ='input data'!C70 -> kPa
B25: Resolution
B26: Ruangan Alat | I26: : | J26: =skorsing!H7 -> lab
B27: Instrument Location
B28: Tanggal Penerimaan Alat | I28: : | J28: =skorsing!H8 -> 46246
B29: Order Received
B30: Tanggal Kalibrasi | I30: : | J30: =skorsing!H9 -> 46246
B31: Calibration Date
B32: Berlaku Sampai Dengan | I32: :
B33: Valid Until
A35: B. | B35: KONDISI RUANGAN
B36: Environment Condition
B37: 1 | C37: Suhu | I37: : | J37: ( | K37: =skorsing!G22 -> 26.088195 | L37: ± | M37: =skorsing!H22 -> 0.5 | N37: )°C
C38: Temperature
B39: 2 | C39: Kelembaban | I39: : | J39: ( | K39: =skorsing!G23 -> 55.691091 | L39: ± | M39: =skorsing!H23 -> 2.7 | N39: )%RH
C40: Humidity
C41: Sumber Tegangan | H41: L-N | I41: : | J41: =skorsing!G24 -> 231.63429 | L41: Vac
C42: Power Supply Voltage
A46: C. | B46: PENGAMATAN KONDISI FISIK DAN FUNGSI
B47: Physcal And Function Inspection Result
B48: 1 | C48: Fisik Alat | I48: : | J48: =Laporan!F68 -> Baik | K48: / | L48: Good
C49: Instrument Physical
B50: 2 | C50: Fungsi Alat | I50: : | J50: =J48 -> Baik | K50: / | L50: Good
C51: Instrument Function
A53: D. | B53: DAFTAR ALAT YANG DIGUNAKAN
B54: List Of Instrument Standard
B55: Nama Alat | H55: Merk | L55: Model/Type | O55: Nomor Seri
...
