Workbook
Name _Toc497991472: 'Input Data'!#REF!
Name _Toc497991473: 'Input Data'!#REF!
Name _Toc497991474: 'Input Data'!#REF!

Sheet Input Data
C2: LEMBAR KERJA KALIBRASI THERMOMETER EAR/THERMOMETER INFRA RED
B4: A. PENDATAAN ADMINISTRASI
B5: No. Sertifikat : | C5: S.248 | E5: No. Alat :
B6: Nama Alat : | C6: Themometer Infrared | E6: Pemilik : | G6: Klinik Asta Nugraha
B7: Merek : | C7: KARKNEE | E7: Ruangan : | G7: Lab Presisi
B8: Model/Tipe : | C8: DT-8806C | E8: Tgl. Terima : | G8: 45880
B9: No. Seri : | C9: 0595-5000 | E9: Tgl. Kalibrasi : | G9: 45884
B10: Kapasitas : | E10: Petugas Kalibrasi : | G10: Eliza Novianti
B11: Resolusi : | C11: 0.1 | D11: ℃
B14: B. DAFTAR ALAT YANG DIGUNAKAN
B15: No | C15: Nama Alat | E15: Merk | F15: Type / Model | G15: No. Seri
B16: 1 | C16: Black Body Liquid Calibration Source | E16: - | F16: - | G16: -
B17: 2 | C17: Thermometer Refrence | E17: - | F17: - | G17: -
B18: 3 | C18: Digital thermohygrometer | E18: Taffware | F18: HTC-1 | G18: TH-01
B21: C. PENGUKURAN KONDISI LINGKUNGAN
B22: Kondisi Ruang | C22: Awal | D22: Akhir | E22: Toleransi
B23: Suhu (°C) | C23: 21 | D23: 21 | E23: 25 ± 1 °C
B24: RH (%) | C24: 52 | D24: 52 | E24: 50 % ± 10 %
B27: D. PEMERIKSAAN FISIK DAN FUNGSI ALAT
B28: Bagian Alat | C28: Keterangan | F28: Hasil Pengamatan
B29: Badan Permukaan | C29: periksa bagian luar unit, pastikan bersih, terpasang ketat satu dan lainnya dan tidak ada bekas tertimpa cairan ataupun gangguan lainnya. | F29: 1 | G29: Baik
G31: Tidak baik
B33: baterai | C33: Pastikan baterai berfungsi dengan baik | F33: 1 | G33: Baik
G35: Tidak baik
B37: tampilan dan indikator | C37: selama pengecekan fungsi, pastikan tampilan indicator dan tampilan berfungsi seluruhnya, yakinkan bahwa tampilan digital berfungsi | F37: 1 | G37: Baik
G38: Tidak baik
B40: E. PENGUKURAN KINERJA ALAT
B41: Thermometer Refrence
B42: Setting Standar ℃ | C42: Pembacaan refrence thermometer | H42: Toleransi
C43: I | D43: II | E43: III | F43: IV | G43: V
B44: 35 | C44: 35.1 | D44: 35.1 | E44: 35.1 | F44: 35.2 | G44: 35.2 | H44: ± 0,3 ℃
B45: 37 | C45: 36.9 | D45: 36.9 | E45: 37.2 | F45: 37.1 | G45: 37.2 | H45: ± 0,2 ℃
B46: 41 | C46: 40.9 | D46: 41.1 | E46: 41.2 | F46: 41.2 | G46: 41.2 | H46: ± 0,3 ℃
B48: Pembacaan UUT
B49: Setting Standar ℃ | C49: Pembacaan UUT | H49: Toleransi
C50: I | D50: II | E50: III | F50: IV | G50: V
B51: 35 | C51: 35.1 | D51: 35 | E51: 35.1 | F51: 35.1 | G51: 35.2 | H51: ± 0,3 ℃
B52: 37 | C52: 37.2 | D52: 37.1 | E52: 37.2 | F52: 37.13 | G52: 37.2 | H52: ± 0,2 ℃
B53: 41 | C53: 41.2 | D53: 41.1 | E53: 41.3 | F53: 41.3 | G53: 41.3 | H53: ± 0,3 ℃
B57: CATATAN:
...

Sheet skorsing
C2: ='Input Data'!C2:H2 -> LEMBAR KERJA KALIBRASI THERMOMETER EAR/THERMOMETER INFRA RED
B4: A. PENDATAAN ADMINISTRASI
B5: No. Sertifikat : | C5: ='Input Data'!C5 -> S.248 | E5: No. Alat : | G5: ='Input Data'!G5:H5 -> 0
B6: Nama Alat : | C6: ='Input Data'!C6 -> Themometer Infrared | E6: Pemilik : | G6: ='Input Data'!G6:H6 -> Klinik Asta Nugraha
B7: Merek : | C7: ='Input Data'!C7 -> KARKNEE | E7: Ruangan : | G7: ='Input Data'!G7:H7 -> Lab Presisi
B8: Model/Tipe : | C8: ='Input Data'!C8 -> DT-8806C | E8: Tgl. Terima : | G8: ='Input Data'!G8:H8 -> 45880
B9: No. Seri : | C9: ='Input Data'!C9 -> 0595-5000 | E9: Tgl. Kalibrasi : | G9: ='Input Data'!G9:H9 -> 45884
B10: Kapasitas : | C10: ='Input Data'!C10 -> 0 | E10: Petugas Kalibrasi : | G10: ='Input Data'!G10:H10 -> Eliza Novianti
B11: Resolusi : | C11: ='Input Data'!C11 -> 0.1 | D11: ℃
B14: B. DAFTAR ALAT YANG DIGUNAKAN | J14: 1 | K14: 2 | L14: 3 | M14: 4 | N14: 5 | O14: 6 | P14: 7 | Q14: 8 | R14: 9 | S14: 10 | T14: 11 | U14: 12 | V14: 13 | W14: 14
B15: No | C15: Nama Alat | E15: Merk | F15: Type / Model | G15: No. Seri | J15: No. Seri | K15: No | L15: Nama | M15: Merk | N15: Type | O15: Regresi Suhu | Q15: Regresi Kelembaban | S15: suhu | T15: Kelembaban | U15: Tgl. Kalibrasi | V15: mean terkoreksi
B16: 1 | C16: ='Input Data'!C16:D16 -> Black Body Liquid Calibration Source | E16: ='Input Data'!E16 -> - | F16: ='Input Data'!F16 -> - | G16: ='Input Data'!G16 -> - | O16: Intercept | P16: X variabel | Q16: Intercept | R16: X variabel | V16: suhu | W16: kelembaban
B17: 2 | C17: ='Input Data'!C17:D17 -> Thermometer Refrence | E17: ='Input Data'!E17 -> - | F17: ='Input Data'!F17 -> - | G17: ='Input Data'!G17 -> - | J17: =[1]ARRAY!D6 -> TH-01 | K17: =[1]ARRAY!E6 -> 1 | L17: =[1]ARRAY!F6 -> Digital thermohygrometer | M17: =[1]ARRAY!G6 -> Taffware | N17: =[1]ARRAY!H6 -> HTC-1 | O17: =[1]ARRAY!I6 -> -0.35317479 | P17: =[1]ARRAY!J6 -> 1.0389536 | Q17: =[1]ARRAY!K6 -> -19.598182 | R17: =[1]ARRAY!L6 -> 1.3814545 | S17: =[2]ARRAY!$M$6 -> 0.5 | T17: =[1]ARRAY!N6 -> 2.7 | U17: =[1]ARRAY!O6 -> 45799 | V17: =O17+P17*$F$23 -> 21.464851 | W17: =Q17+R17*$F$24 -> 52.237455
B18: 3 | C18: ='Input Data'!C18:D18 -> Digital thermohygrometer | E18: ='Input Data'!E18 -> Taffware | F18: ='Input Data'!F18 -> HTC-1 | G18: ='Input Data'!G18 -> TH-01 | J18: =[1]ARRAY!D7 -> TH-02 | K18: =[1]ARRAY!E7 -> 2 | L18: =[1]ARRAY!F7 -> Digital thermohygrometer | M18: =[1]ARRAY!G7 -> Taffware | N18: =[1]ARRAY!H7 -> HTC-1 | O18: =[1]ARRAY!I7 -> -0.036218787 | P18: =[1]ARRAY!J7 -> 1.023044 | Q18: =[1]ARRAY!K7 -> -20.981818 | R18: =[1]ARRAY!L7 -> 1.3290909 | S18: =[2]ARRAY!$M$6 -> 0.5 | T18: =[1]ARRAY!N7 -> 3.1 | U18: =[1]ARRAY!O7 -> 45799 | V18: =O18+P18*$F$23 -> 21.447705 | W18: =Q18+R18*$F$24 -> 48.130909
J19: =[1]ARRAY!D8 -> TH-03 | K19: =[1]ARRAY!E8 -> 3 | L19: =[1]ARRAY!F8 -> Digital thermohygrometer | M19: =[1]ARRAY!G8 -> Taffware | N19: =[1]ARRAY!H8 -> HTC-1 | O19: =[1]ARRAY!I8 -> -0.40318668 | P19: =[1]ARRAY!J8 -> 1.0430321 | Q19: =[1]ARRAY!K8 -> -19.666364 | R19: =[1]ARRAY!L8 -> 1.3078182 | S19: =[2]ARRAY!$M$6 -> 0.5 | T19: =[1]ARRAY!N8 -> 2.7 | U19: =[1]ARRAY!O8 -> 45799 | V19: =O19+P19*$F$23 -> 21.500488 | W19: =Q19+R19*$F$24 -> 48.340182
J20: =[1]ARRAY!D9 -> TH-04 | K20: =[1]ARRAY!E9 -> 4 | L20: =[1]ARRAY!F9 -> Digital thermohygrometer | M20: =[1]ARRAY!G9 -> Taffware | N20: =[1]ARRAY!H9 -> HTC-1 | O20: =[1]ARRAY!I9 -> 0.19985731 | P20: =[1]ARRAY!J9 -> 0.99894174 | Q20: =[1]ARRAY!K9 -> -20.05 | R20: =[1]ARRAY!L9 -> 1.3190909 | S20: =[2]ARRAY!$M$6 -> 0.5 | T20: =[1]ARRAY!N9 -> 2.9 | U20: =[1]ARRAY!O9 -> 45799 | V20: =O20+P20*$F$23 -> 21.177634 | W20: =Q20+R20*$F$24 -> 48.542727
B21: C. PENGUKURAN KONDISI LINGKUNGAN
B22: Kondisi Ruang | C22: Awal | D22: Akhir | E22: Toleransi | F22: mean | G22: mean terkoreksi | I22: ktps
B23: Suhu (°C) | C23: ='Input Data'!C23 -> 21 | D23: ='Input Data'!D23 -> 21 | E23: 25 ± 6 °C | F23: =AVERAGE(C23:D23) -> 21 | G23: =VLOOKUP(G18,J17:W20,13,FALSE) -> 21.464851 | I23: =VLOOKUP(G18,J17:W20,10,FALSE) -> 0.5
B24: RH (%) | C24: ='Input Data'!C24 -> 52 | D24: ='Input Data'!D24 -> 52 | E24: 55 % ± 20 % | F24: =AVERAGE(C24:D24) -> 52 | G24: =VLOOKUP(G18,J17:W20,14,FALSE) -> 52.237455 | I24: =VLOOKUP(G18,J17:W20,11,FALSE) -> 2.7
B26: D. PEMERIKSAAN FISIK DAN FUNGSI ALAT
B27: Bagian Alat | C27: Keterangan | F27: Hasil Pengamatan | H27: Hasil | I27: Bobot
B28: ='Input Data'!B29 -> Badan Permukaan | C28: ='Input Data'!C29 -> periksa bagian luar unit, pastikan bersih, terpasang ketat satu dan lainnya dan tidak ada bekas tertimpa cairan ataupun gangguan lainnya. | F28: ='Input Data'!F29 -> 1 | G28: Baik | H28: =IF(F28=1,"LULUS","TIDAK LULUS") -> LULUS | I28: =(COUNTIF(H28:H37,"LULUS")/(COUNTA(H28:H37))*10) -> 10
G30: Tidak baik
B32: ='Input Data'!B33 -> baterai | C32: ='Input Data'!C33 -> Pastikan baterai berfungsi dengan baik | F32: ='Input Data'!F33 -> 1 | G32: Baik | H32: =IF(F32=1,"LULUS","TIDAK LULUS") -> LULUS
G34: Tidak baik
B36: ='Input Data'!B37 -> tampilan dan indikator | C36: ='Input Data'!C37 -> selama pengecekan fungsi, pastikan tampilan indicator dan tampilan berfungsi seluruhnya, yakinkan bahwa tampilan digital berfungsi | F36: ='Input Data'!F37 -> 1 | G36: Baik | H36: =IF(F36=1,"LULUS","TIDAK LULUS") -> LULUS
G37: Tidak baik
B39: E. PENGUKURAN KINERJA ALAT
B40: ='Input Data'!B41 -> Thermometer Refrence
B41: Setting simulator | C41: Pembacaan Thermometer Refrence
C42: I | D42: II | E42: III | F42: IV | G42: V
B43: ='Input Data'!B44 -> 35 | C43: ='Input Data'!C44 -> 35.1 | D43: ='Input Data'!D44 -> 35.1 | E43: ='Input Data'!E44 -> 35.1 | F43: ='Input Data'!F44 -> 35.2 | G43: ='Input Data'!G44 -> 35.2
B44: ='Input Data'!B45 -> 37 | C44: ='Input Data'!C45 -> 36.9 | D44: ='Input Data'!D45 -> 36.9 | E44: ='Input Data'!E45 -> 37.2 | F44: ='Input Data'!F45 -> 37.1 | G44: ='Input Data'!G45 -> 37.2
B45: ='Input Data'!B46 -> 41 | C45: ='Input Data'!C46 -> 40.9 | D45: ='Input Data'!D46 -> 41.1 | E45: ='Input Data'!E46 -> 41.2 | F45: ='Input Data'!F46 -> 41.2 | G45: ='Input Data'!G46 -> 41.2
B47: thermometer UUT
B48: Setting simulator | C48: Pembacaan UUT | H48: terkoreksi | M48: mean terkoreksi UUT | N48: mean pemb refrence | O48: koreksi | P48: STDV | Q48: ESDM | R48: KTPS | S48: toleransi | T48: hasil | U48: score
C49: I | D49: II | E49: III | F49: IV | G49: V | H49: I | I49: II | J49: III | K49: IV | L49: V
B50: ='Input Data'!B51 -> 35 | C50: ='Input Data'!C51 -> 35.1 | D50: ='Input Data'!D51 -> 35 | E50: ='Input Data'!E51 -> 35.1 | F50: ='Input Data'!F51 -> 35.1 | G50: ='Input Data'!G51 -> 35.2 | H50: =C50 -> 35.1 | I50: =D50 -> 35 | J50: =E50 -> 35.1 | K50: =F50 -> 35.1 | L50: =G50 -> 35.2 | M50: =AVERAGE(H50:L50) -> 35.1 | N50: =AVERAGE(C43:G43) -> 35.14 | O50: =M50-B50 -> 0.1 | P50: =STDEV(C50:G50) -> 0.070710678 | Q50: =P50/SQRT(5) -> 0.031622777 | R50: =budget!K15 -> 0.093291192 | S50: 0.3 | T50: =IF(ABS(O50)+R50<=(S50+R50),"Lulus","Tidak Lulus") -> Lulus | U50: =COUNTIF(T50:T52,"LULUS")/(COUNTA(T50:T52))*90 -> 90
B51: ='Input Data'!B52 -> 37 | C51: ='Input Data'!C52 -> 37.2 | D51: ='Input Data'!D52 -> 37.1 | E51: ='Input Data'!E52 -> 37.2 | F51: ='Input Data'!F52 -> 37.13 | G51: ='Input Data'!G52 -> 37.2 | H51: =C51 -> 37.2 | I51: =D51 -> 37.1 | J51: =E51 -> 37.2 | K51: =F51 -> 37.13 | L51: =G51 -> 37.2 | M51: =AVERAGE(H51:L51) -> 37.166 | N51: =AVERAGE(C44:G44) -> 37.06 | O51: =M51-B51 -> 0.166 | P51: =STDEV(C51:G51) -> 0.047749346 | Q51: =P51/SQRT(5) -> 0.021354157 | R51: =budget!K29 -> 0.073952444 | S51: 0.2 | T51: =IF(ABS(O51)+R51<=(S51+R51),"Lulus","Tidak Lulus") -> Lulus
...

Sheet budget
B1: PERHITUNGAN KETIDAKPASTIAN
B3: Setting : 35°C
B4: Komponen | C4: Satuan | D4: Distribusi | E4: Stdev (U) | F4: Pembagi | G4: v | H4: u | I4: c | J4: (u.c) | K4: (u.c)² | L4: (u.c)⁴/v
B5: Repeatability | C5: °C | D5: Normal | E5: =skorsing!Q50 -> 0.031622777 | F5: 1 | G5: =5-1 -> 4 | H5: =E5/F5 -> 0.031622777 | I5: 1 | J5: =H5*I5 -> 0.031622777 | K5: =J5^2 -> 0.001 | L5: =J5^4/G5 -> 2.5e-07
B6: Sertif Standard | C6: °C | D6: Normal | E6: 0 | F6: 2 | G6: 50 | H6: =E6/F6 -> 0 | I6: 1 | J6: =H6*I6 -> 0 | K6: =J6^2 -> 0 | L6: =J6^4/G6 -> 0
B7: Homogenitas Blackbody | C7: °C | D7: Rectangular | E7: 0 | F7: =SQRT(3) -> 1.7320508 | G7: 50 | H7: =E7/F7 -> 0 | I7: 1 | J7: =H7*I7 -> 0 | K7: =J7^2 -> 0 | L7: =J7^4/G7 -> 0
B8: Stabilitas Blackbody | C8: °C | D8: Rectangular | E8: 0 | F8: =SQRT(3) -> 1.7320508 | G8: 50 | H8: =E8/F8 -> 0 | I8: 1 | J8: =H8*I8 -> 0 | K8: =J8^2 -> 0 | L8: =J8^4/G8 -> 0
B9: Drift | C9: °C | D9: Rectangular | E9: 0 | F9: =SQRT(3) -> 1.7320508 | G9: 50 | H9: =E9/F9 -> 0 | I9: 1 | J9: =H9*I9 -> 0 | K9: =J9^2 -> 0 | L9: =J9^4/G9 -> 0
B10: Resolusi | C10: °C | D10: Rectangular | E10: =0.5*skorsing!$C$11 -> 0.05 | F10: =SQRT(3) -> 1.7320508 | G10: 50 | H10: =E10/F10 -> 0.028867513 | I10: 1 | J10: =H10*I10 -> 0.028867513 | K10: =J10^2 -> 0.00083333333 | L10: =J10^4/G10 -> 1.3888889e-08
B11: Jumlah | K11: =SUM(K5:K10) -> 0.0018333333 | L11: =SUM(L5:L10) -> 2.6388889e-07
B12: Ketidakpastian Baku Gabungan uc | K12: =SQRT(K11) -> 0.042817442
B13: Derajat Kebebasan efektif veff | K13: =K12^4/L11 -> 12.736842
B14: Faktor cakupan, k-student untuk Veff dan CL 95% | K14: =TINV(0.05,K13) -> 2.1788128
B15: Ketidakpastian bentangan, U=k.Uc | K15: =K14*K12 -> 0.093291192
B17: Setting : 37°C
B18: Komponen | C18: Satuan | D18: Distribusi | E18: Stdev (U) | F18: Pembagi | G18: v | H18: u | I18: c | J18: (u.c) | K18: (u.c)² | L18: (u.c)⁴/v
B19: Repeatability | C19: °C | D19: Normal | E19: =skorsing!Q51 -> 0.021354157 | F19: 1 | G19: =5-1 -> 4 | H19: =E19/F19 -> 0.021354157 | I19: 1 | J19: =H19*I19 -> 0.021354157 | K19: =J19^2 -> 0.000456 | L19: =J19^4/G19 -> 5.1984e-08
B20: Sertif Standard | C20: °C | D20: Normal | E20: 0 | F20: 2 | G20: 50 | H20: =E20/F20 -> 0 | I20: 1 | J20: =H20*I20 -> 0 | K20: =J20^2 -> 0 | L20: =J20^4/G20 -> 0
B21: Homogenitas Blackbody | C21: °C | D21: Rectangular | E21: 0 | F21: =SQRT(3) -> 1.7320508 | G21: 50 | H21: =E21/F21 -> 0 | I21: 1 | J21: =H21*I21 -> 0 | K21: =J21^2 -> 0 | L21: =J21^4/G21 -> 0
B22: Stabilitas Blackbody | C22: °C | D22: Rectangular | E22: 0 | F22: =SQRT(3) -> 1.7320508 | G22: 50 | H22: =E22/F22 -> 0 | I22: 1 | J22: =H22*I22 -> 0 | K22: =J22^2 -> 0 | L22: =J22^4/G22 -> 0
B23: Drift | C23: °C | D23: Rectangular | E23: 0 | F23: =SQRT(3) -> 1.7320508 | G23: 50 | H23: =E23/F23 -> 0 | I23: 1 | J23: =H23*I23 -> 0 | K23: =J23^2 -> 0 | L23: =J23^4/G23 -> 0
B24: Resolusi | C24: °C | D24: Rectangular | E24: =0.5*skorsing!$C$11 -> 0.05 | F24: =SQRT(3) -> 1.7320508 | G24: 50 | H24: =E24/F24 -> 0.028867513 | I24: 1 | J24: =H24*I24 -> 0.028867513 | K24: =J24^2 -> 0.00083333333 | L24: =J24^4/G24 -> 1.3888889e-08
B25: Jumlah | K25: =SUM(K19:K24) -> 0.0012893333 | L25: =SUM(L19:L24) -> 6.5872889e-08
B26: Ketidakpastian Baku Gabungan uc | K26: =SQRT(K25) -> 0.035907288
B27: Derajat Kebebasan efektif veff | K27: =K26^4/L25 -> 25.236186
B28: Faktor cakupan, k-student untuk Veff dan CL 95% | K28: =TINV(0.05,K27) -> 2.0595386
B29: Ketidakpastian bentangan, U=k.Uc | K29: =K28*K26 -> 0.073952444
B31: Setting : 41°C
B32: Komponen | C32: Satuan | D32: Distribusi | E32: Stdev (U) | F32: Pembagi | G32: v | H32: u | I32: c | J32: (u.c) | K32: (u.c)² | L32: (u.c)⁴/v
B33: Repeatability | C33: °C | D33: Normal | E33: =skorsing!Q52 -> 0.04 | F33: 1 | G33: =5-1 -> 4 | H33: =E33/F33 -> 0.04 | I33: 1 | J33: =H33*I33 -> 0.04 | K33: =J33^2 -> 0.0016 | L33: =J33^4/G33 -> 6.4e-07
B34: Sertif Standard | C34: °C | D34: Normal | E34: 0 | F34: 2 | G34: 50 | H34: =E34/F34 -> 0 | I34: 1 | J34: =H34*I34 -> 0 | K34: =J34^2 -> 0 | L34: =J34^4/G34 -> 0
B35: Homogenitas Blackbody | C35: °C | D35: Rectangular | E35: 0 | F35: =SQRT(3) -> 1.7320508 | G35: 50 | H35: =E35/F35 -> 0 | I35: 1 | J35: =H35*I35 -> 0 | K35: =J35^2 -> 0 | L35: =J35^4/G35 -> 0
B36: Stabilitas Blackbody | C36: °C | D36: Rectangular | E36: 0 | F36: =SQRT(3) -> 1.7320508 | G36: 50 | H36: =E36/F36 -> 0 | I36: 1 | J36: =H36*I36 -> 0 | K36: =J36^2 -> 0 | L36: =J36^4/G36 -> 0
B37: Drift | C37: °C | D37: Rectangular | E37: 0 | F37: =SQRT(3) -> 1.7320508 | G37: 50 | H37: =E37/F37 -> 0 | I37: 1 | J37: =H37*I37 -> 0 | K37: =J37^2 -> 0 | L37: =J37^4/G37 -> 0
B38: Resolusi | C38: °C | D38: Rectangular | E38: =0.5*skorsing!$C$11 -> 0.05 | F38: =SQRT(3) -> 1.7320508 | G38: 50 | H38: =E38/F38 -> 0.028867513 | I38: 1 | J38: =H38*I38 -> 0.028867513 | K38: =J38^2 -> 0.00083333333 | L38: =J38^4/G38 -> 1.3888889e-08
B39: Jumlah | K39: =SUM(K33:K38) -> 0.0024333333 | L39: =SUM(L33:L38) -> 6.5388889e-07
B40: Ketidakpastian Baku Gabungan uc | K40: =SQRT(K39) -> 0.049328829
B41: Derajat Kebebasan efektif veff | K41: =K40^4/L39 -> 9.0552251
B42: Faktor cakupan, k-student untuk Veff dan CL 95% | K42: =TINV(0.05,K41) -> 2.2621572
B43: Ketidakpastian bentangan, U=k.Uc | K43: =K42*K40 -> 0.11158956

Sheet Laporan
C2: LEMBAR KERJA KALIBRASI THERMOMETER EAR / THERMOMETER INFRARED
B4: A. PENDATAAN ADMINISTRASI
C5: Nama Pelanggan : | D5: =skorsing!G6 -> Klinik Asta Nugraha | E5: Resolusi : | F5: =skorsing!C11 -> 0.1 | G5: ℃
C6: Nama Alat : | D6: =skorsing!C6 -> Themometer Infrared | E6: Rentang Ukur :
E7: Ruangan Tempat Alat : | F7: =skorsing!G7 -> Lab Presisi
C8: Merek : | D8: =skorsing!C7 -> KARKNEE | E8: Tgl. Terima | F8: =skorsing!G8 -> 45880
C9: Model/Tipe : | D9: =skorsing!C8 -> DT-8806C | E9: Tgl. Kalibrasi | F9: =skorsing!G9 -> 45884
C10: No. Seri : | D10: =skorsing!C9 -> 0595-5000 | E10: Nama Petugas Kalibrasi : | F10: =skorsing!G10 -> Eliza Novianti
B13: B. DAFTAR ALAT YANG DIGUNAKAN
B14: No | C14: Nama Alat | E14: Merk | F14: Tipe / Model | G14: No. Seri
B15: 1 | C15: =skorsing!C16 -> Black Body Liquid Calibration Source | E15: =skorsing!E16 -> - | F15: =skorsing!F16 -> - | G15: =skorsing!G16 -> -
B16: 2 | C16: =skorsing!C17 -> Thermometer Refrence | E16: =skorsing!E17 -> - | F16: =skorsing!F17 -> - | G16: =skorsing!G17 -> -
B17: 3 | C17: =skorsing!C18 -> Digital thermohygrometer | E17: =skorsing!E18 -> Taffware | F17: =skorsing!F18 -> HTC-1 | G17: =skorsing!G18 -> TH-01
B19: C. PENGUKURAN KONDISI LINGKUNGAN
B20: Kondisi Ruang | C20: terkoreksi | D20: ktps
B21: Suhu (°C) | C21: =skorsing!G23 -> 21.464851 | D21: =skorsing!I23 -> 0.5
B22: RH (%) | C22: =skorsing!G24 -> 52.237455 | D22: =skorsing!I24 -> 2.7
B24: D. PEMERIKSAAN FISIK DAN FUNGSI ALAT
B25: Bagian Alat | C25: Keterangan | F25: Hasil Pengamatan
B26: =skorsing!B28 -> Badan Permukaan | C26: =skorsing!C28 -> periksa bagian luar unit, pastikan bersih, terpasang ketat satu dan lainnya dan tidak ada bekas tertimpa cairan ataupun gangguan lainnya. | F26: =IF([3]skorsing!F30=1,"BAIK","TIDAK BAIK") -> BAIK
B28: =skorsing!B32 -> baterai | C28: =skorsing!C32 -> Pastikan baterai berfungsi dengan baik | F28: =IF([3]skorsing!F34=1,"BAIK","TIDAK BAIK") -> BAIK
B30: =skorsing!B36 -> tampilan dan indikator | C30: =skorsing!C36 -> selama pengecekan fungsi, pastikan tampilan indicator dan tampilan berfungsi seluruhnya, yakinkan bahwa tampilan digital berfungsi | F30: =IF([3]skorsing!F38=1,"BAIK","TIDAK BAIK") -> BAIK
B34: E. PENGUKURAN KINERJA ALAT
B35: =skorsing!B39 -> E. PENGUKURAN KINERJA ALAT
B36: Setting Simulator (℃) | C36: penunjukan Refrence | D36: Pembacaan UUT | E36: koreksi | F36: ketidakpastian
B37: =skorsing!B50 -> 35 | C37: =skorsing!N50 -> 35.14 | D37: =skorsing!M50 -> 35.1 | E37: =skorsing!O50 -> 0.1 | F37: =skorsing!R50 -> 0.093291192
B38: =skorsing!B51 -> 37 | C38: =skorsing!N51 -> 37.06 | D38: =skorsing!M51 -> 37.166 | E38: =skorsing!O51 -> 0.166 | F38: =skorsing!R51 -> 0.073952444
B39: =skorsing!B52 -> 41 | C39: =skorsing!N52 -> 41.12 | D39: =skorsing!M52 -> 41.24 | E39: =skorsing!O52 -> 0.24 | F39: =skorsing!R52 -> 0.11158956
B42: VI. Kesimpulan
B43: a | C43: Pengujian fisik dan fungsi dinyatakan : | F43: =IF(skorsing!I28>=10,"Baik","Tidak Baik") -> Baik
B44: b | C44: Alat dinyatakan | D44: =IF(skorsing!C54>=70,"Alat Dinyatakan Laik Pakai","Alat Dinyatakan Tidak Laik Pakai") -> Alat Dinyatakan Laik Pakai
B45: n | C45: Disarankan agar dilakukan kalibrasi ulang sesuai jadwal secara berkala

Sheet Cover
L8: Nomor Sertifikat | P8: : | Q8: =skorsing!C5 -> S.248
L9: Certificate Number
A11: SERTIFIKAT KALIBRASI
A12: Calibration Certificate
B13: DATA ALAT
B14: Instrument ID
C15: Nama Alat | F15: : | G15: =Laporan!D6 -> Themometer Infrared
C16: Device Name
C17: Merk | F17: : | G17: =Laporan!D8 -> KARKNEE
C18: Brand
C19: Type/Model | F19: : | G19: =Laporan!D9 -> DT-8806C
C20: Type/Model
C21: Nomor Seri | F21: : | G21: =Laporan!D10 -> 0595-5000
C22: Serial Number
C23: Resolusi | F23: : | G23: =Laporan!F5 -> 0.1 | H23: ℃
C24: Resolution
B26: IDENTITAS PELANGGAN
B27: Customer ID
C28: Pelanggan | F28: : | G28: =Laporan!D5 -> Klinik Asta Nugraha
C29: Customer
C30: Alamat | F30: : | G30: Jl. Duren Sawit Raya (dermaga) No.19 Blok K1, RT.9/RW.11, Klender, Durensawit, East Jakarta City, Jakarta 13470
C31: Address
I33: Sertifikat ini terdiri dari | N33: : | O33: 4 halaman
I34: This certificate consist of
I35: Diterbitkan tanggal | N35: : | O35: 45889
I36: Published date
K38: PT. Presisi Kalibrasi Medika
K42: Samsurizal
K43: Direktur
K44: Director

Sheet Laporan Print
L8: Nomor Sertifikat | P8: : | Q8: =Cover!Q8 -> S.248
L9: Certificate Number
A12: LAPORAN KALIBRASI
A13: Calibration Report
A14: =Laporan!D6 -> Themometer Infrared
A16: A. | B16: PENDATAAN ADMINISTRASI
B17: Administration
B18: Merk | I18: : | J18: =Laporan!D8 -> KARKNEE
B19: Brand
B20: Type/Model | I20: : | J20: =Laporan!D9 -> DT-8806C
B21: Type/Model
B22: Nomor Seri | I22: : | J22: =Laporan!D10 -> 0595-5000
B23: Serial Number
B24: Resolusi | I24: : | J24: =Laporan!F5 -> 0.1 | K24: ℃
B25: Resolution
B26: Ruangan Alat | I26: : | J26: =Laporan!F7 -> Lab Presisi
B27: Instrument Location
B28: Tanggal Penerimaan Alat | I28: : | J28: =Laporan!F8 -> 45880
B29: Order Received
B30: Tanggal Kalibrasi | I30: : | J30: =Laporan!F9 -> 45884
B31: Calibration Date
B32: Berlaku Sampai Dengan | I32: : | J32: 46249
B33: Valid Until
A35: B. | B35: KONDISI RUANGAN
B36: Environment Condition
B37: 1 | C37: Suhu | I37: : | J37: ( | K37: =Laporan!C21 -> 21.464851 | L37: ± | M37: =Laporan!D21 -> 0.5 | N37: )°C
C38: Temperature
B39: 2 | C39: Kelembaban | I39: : | J39: ( | K39: =Laporan!C22 -> 52.237455 | L39: ± | M39: =Laporan!D22 -> 2.7 | N39: )%RH
C40: Humidity
A46: C. | B46: PENGAMATAN KONDISI FISIK DAN FUNGSI
B47: Physcal And Function Inspection Result
B48: 1 | C48: Fisik Alat | I48: : | J48: =Laporan!F43 -> Baik | K48: / | L48: Good
C49: Instrument Physical
B50: 2 | C50: Fungsi Alat | I50: : | J50: =J48 -> Baik | K50: / | L50: Good
C51: Instrument Function
A53: D. | B53: DAFTAR ALAT YANG DIGUNAKAN
B54: List Of Instrument Standard
B55: Nama Alat | H55: Merk | L55: Model/Type | O55: Nomor Seri
B56: Instrument standard | H56: Brand | L56: Model/Type | O56: Serial Number
B57: =Laporan!C15 -> Black Body Liquid Calibration Source | H57: =Laporan!E15 -> - | L57: - | O57: =Laporan!G15 -> -
...
