Workbook

Sheet Input data
C2: LEMBAR KERJA PENGUJIAN URINE ANALYZER
B4: A. PENDATAAN ADMINISTRASI
C5: No. Sertifikat : | D5: S.612 | F5: No. Alat :
C6: Nama Alat : | D6: Urine Analyzer | F6: Pemilik : | H6: PT. Presisi Kalibrasi Medika
C7: Merek : | D7: SM | F7: Ruangan : | H7: R. Laboratorium
C8: Model/Tipe : | D8: SM S-600 | F8: Tgl. Terima : | H8: 46266
C9: No. Seri : | D9: 111 | F9: Tgl. Kalibrasi : | H9: 46266
C10: Kapasitas : | F10: Petugas Kalibrasi : | H10: el
C11: resolusi: | D11: 1
B12: B. DAFTAR ALAT YANG DIGUNAKAN
B13: No | C13: Nama Alat | E13: Merk | F13: Type / Model | G13: No. Seri
B14: 1 | C14: Kontrol Standard / CRM | E14: - | F14: - | G14: -
B15: 2 | C15: Electrical Safety Analyzer | E15: Fluke Biomedical | F15: ESA612 | G15: 6579027
B16: 3 | C16: Thermohygrometer | E16: Taffware | F16: HTC-1 | G16: TH-01
B19: C. PENGUKURAN KONDISI LINGKUNGAN
C20: Kondisi Ruang | D20: Awal | E20: Akhir | F20: Toleransi
C21: Suhu (°C) | D21: 23.1 | E21: 23.3 | F21: 25 ± 5 °C
C22: RH (%) | D22: 53 | E22: 53 | F22: 55 % ± 20 %
C23: Tegangan | D23: L-N | E23: 221.1 | F23: 220 ± 10% Vac
D24: L-G | E24: 87.5
D25: N-G | E25: 137.2
B28: D. PEMERIKSAAN FISIK DAN FUNGSI ALAT
C29: Bagian Alat | D29: Keterangan | G29: Hasil Pengamatan
C30: Badan Permukaan | D30: Selungkup utuh, bersih, terpasang ketat satu dan yang lainnya serta tidak ada bekas tertimpa cairan ataupun gangguan | G30: 1 | H30: Baik
H31: Tidak baik
C32: Kotak kontak alat | D32: periksa apakah ada gangguan pada kotak kontak (AC-Power). Gerak-gerakkan kotak kontak untuk memastikan keamanannya. Goyang-goyangkan kotak kontak untuk memastikan tidak ada baut atau mur yang longgar. | G32: 1 | H32: Baik
H33: Tidak baik
C34: Kabel catu utama | D34: periksa kabel, apakah terlihat ada kerusakan atau bagian isolasi yang terkelupas. | G34: 1 | H34: Baik
H35: Tidak baik
C36: Tombol, Saklar dan pengaman | D36: sebelum mempergunakan/mengubah-ubah tombol kontrol, periksa posisinya, jika terlihat tidak berada pada posisinya (periksa dengan menggunakan mode pemeriksaan standar). Bandingkan dengan posisi control. Ingat peraturan tersebut dan jangan lupa untuk mengembalikan pada setting awal jika sudah selesai menggunakan. | G36: 1 | H36: Baik
H37: Tidak baik
C38: Tampilan indikator | D38: Pastikan lampu indikator dan bagian tampilan digital berfungsi seluruhnya | G38: 1 | H38: Baik
H39: Tidak baik
B41: E. PENGUKURAN KESELAMATAN LISTRIK
B42: Tipe bagian yang diaplikasikan | E42: B | F42: BF | G42: CF
B43: Kelas proteksi | E43: I | F43: II | G43: Baterai
B44: Hubungan utama | E44: DPS | F44: NPS | G44: PIE
B45: Catatan | E45: PIE : peralatan yang diinstalasi permanen
E46: NPS : kabel catu daya yang tidak dapat dilepas
E47: Kabel catu daya yang dapat dilepas
...

Sheet Skorsing
C2: LEMBAR KERJA PENGUJIAN HEMATOLOGI ANALYZER
B4: A. PENDATAAN ADMINISTRASI
C5: No. Sertifikat : | D5: ='Input data'!D5 -> S.612 | F5: No. Alat : | H5: ='Input data'!H5 -> 0
C6: Nama Alat : | D6: ='Input data'!D6 -> Urine Analyzer | F6: Pemilik : | H6: ='Input data'!H6 -> PT. Presisi Kalibrasi Medika
C7: Merek : | D7: ='Input data'!D7 -> SM | F7: Ruangan : | H7: ='Input data'!H7 -> R. Laboratorium
C8: Model/Tipe : | D8: ='Input data'!D8 -> SM S-600 | F8: Tgl. Terima : | H8: ='Input data'!H8 -> 46266
C9: No. Seri : | D9: ='Input data'!D9 -> 111 | F9: Tgl. Kalibrasi : | H9: ='Input data'!H9 -> 46266
C10: Kapasitas : | D10: ='Input data'!D10 -> 0 | F10: Petugas Kalibrasi : | H10: ='Input data'!H10 -> el
C11: Resolusi : | D11: ='Input data'!D11 -> 1
B13: B. DAFTAR ALAT YANG DIGUNAKAN
B14: No | C14: Nama Alat | E14: Merk | F14: Type / Model | G14: No. Seri
B15: 1 | C15: ='Input data'!#REF! -> #REF! | E15: ='Input data'!#REF! -> #REF! | F15: ='Input data'!#REF! -> #REF! | G15: ='Input data'!#REF! -> #REF!
B16: 2 | C16: ='Input data'!C14 -> Kontrol Standard / CRM | E16: ='Input data'!E14 -> - | F16: ='Input data'!F14 -> - | G16: ='Input data'!G14 -> -
B17: 3 | C17: ='Input data'!C15 -> Electrical Safety Analyzer | E17: ='Input data'!E15 -> Fluke Biomedical | F17: ='Input data'!F15 -> ESA612 | G17: ='Input data'!G15 -> 6579027
B18: 4 | C18: ='Input data'!C16 -> Thermohygrometer | E18: ='Input data'!E16 -> Taffware | F18: ='Input data'!F16 -> HTC-1 | G18: ='Input data'!G16 -> TH-01
B21: C. PENGUKURAN KONDISI LINGKUNGAN | S21: 1 | T21: 2 | U21: 3 | V21: 5 | W21: 6 | X21: 7 | Y21: 8 | Z21: 9 | AA21: 10 | AB21: 11 | AC21: 12 | AD21: 13 | AE21: 14
C22: Kondisi Ruang | D22: Awal | E22: Akhir | F22: Toleransi | G22: mean | H22: mean terkoreksi | I22: ktps | S22: No. Seri | T22: No | U22: Nama | V22: Type | W22: Regresi Suhu | Y22: Regresi Kelembaban | AA22: U95 | AC22: Tgl. Kalibrasi | AD22: Mean Terkoreksi
C23: Suhu (°C) | D23: ='Input data'!D21 -> 23.1 | E23: ='Input data'!E21 -> 23.3 | F23: ='[1]Input Data'!F25 -> 25 ± 5 °C | G23: =AVERAGE(D23:E23) -> 23.2 | H23: =VLOOKUP(G18,S24:AE27,12,FALSE) -> 23.750549 | I23: =VLOOKUP(G18,S24:AE27,9,FALSE) -> 0.5 | W23: Intercept | X23: X variabel | Y23: Intercept | Z23: X variabel | AA23: Suhu | AB23: Kelembaban | AD23: Suhu | AE23: Kelelmbaban
C24: RH (%) | D24: ='Input data'!D22 -> 53 | E24: ='Input data'!E22 -> 53 | F24: ='[1]Input Data'!F26 -> 55 % ± 20 % | G24: =AVERAGE(D24:E24) -> 53 | H24: =VLOOKUP(G18,S24:AE27,13,FALSE) -> 53.618909 | I24: =VLOOKUP(G18,S24:AE27,10,FALSE) -> 2.7 | S24: =[2]ARRAY!D6 -> TH-01 | T24: 1 | U24: Digital thermohygrometer | V24: =[2]ARRAY!H6 -> HTC-1 | W24: =[2]ARRAY!I6 -> -0.35317479 | X24: =[2]ARRAY!J6 -> 1.0389536 | Y24: =[2]ARRAY!K6 -> -19.598182 | Z24: =[2]ARRAY!L6 -> 1.3814545 | AA24: =[2]ARRAY!M6 -> 0.5 | AB24: =[2]ARRAY!N6 -> 2.7 | AC24: =[2]ARRAY!O6 -> 45799 | AD24: =W24+X24*$G$23 -> 23.750549 | AE24: =Y24+Z24*$G$24 -> 53.618909
C25: Tegangan | D25: ='[1]Input Data'!D27 -> L-N | E25: ='Input data'!E23 -> 221.1 | F25: Vac | H25: =VLOOKUP(G17,ESA!B12:I12,5,FALSE) -> 221.23674 | S25: =[2]ARRAY!D7 -> TH-02 | T25: 2 | U25: Digital thermohygrometer | V25: =[2]ARRAY!H7 -> HTC-1 | W25: =[2]ARRAY!I7 -> -0.036218787 | X25: =[2]ARRAY!J7 -> 1.023044 | Y25: =[2]ARRAY!K7 -> -20.981818 | Z25: =[2]ARRAY!L7 -> 1.3290909 | AA25: =[2]ARRAY!M7 -> 0.5 | AB25: =[2]ARRAY!N7 -> 3.1 | AC25: =[2]ARRAY!O7 -> 45799 | AD25: =W25+X25*$G$23 -> 23.698402 | AE25: =Y25+Z25*$G$24 -> 49.46
D26: ='[1]Input Data'!D28 -> L-G | E26: ='Input data'!E24 -> 87.5 | F26: Vac | S26: =[2]ARRAY!D8 -> TH-03 | T26: 3 | U26: Digital thermohygrometer | V26: =[2]ARRAY!H8 -> HTC-1 | W26: =[2]ARRAY!I8 -> -0.40318668 | X26: =[2]ARRAY!J8 -> 1.0430321 | Y26: =[2]ARRAY!K8 -> -19.666364 | Z26: =[2]ARRAY!L8 -> 1.3078182 | AA26: =[2]ARRAY!M8 -> 0.5 | AB26: =[2]ARRAY!N8 -> 2.7 | AC26: =[2]ARRAY!O8 -> 45799 | AD26: =W26+X26*$G$23 -> 23.795158 | AE26: =Y26+Z26*$G$24 -> 49.648
D27: ='[1]Input Data'!D29 -> N-G | E27: ='Input data'!E25 -> 137.2 | F27: Vac | S27: =[2]ARRAY!D9 -> TH-04 | T27: 4 | U27: Digital thermohygrometer | V27: =[2]ARRAY!H9 -> HTC-1 | W27: =[2]ARRAY!I9 -> 0.19985731 | X27: =[2]ARRAY!J9 -> 0.99894174 | Y27: =[2]ARRAY!K9 -> -20.05 | Z27: =[2]ARRAY!L9 -> 1.3190909 | AA27: =[2]ARRAY!M9 -> 0.6 | AB27: =[2]ARRAY!N9 -> 2.9 | AC27: =[2]ARRAY!O9 -> 45799 | AD27: =W27+X27*$G$23 -> 23.375306 | AE27: =Y27+Z27*$G$24 -> 49.861818
B30: D. PEMERIKSAAN FISIK DAN FUNGSI ALAT
C31: Bagian Alat | D31: Keterangan | G31: Hasil Pengamatan | I31: Hasil | J31: Bobot | K31: Score
C32: ='Input data'!C30 -> Badan Permukaan | D32: ='Input data'!D30 -> Selungkup utuh, bersih, terpasang ketat satu dan yang lainnya serta tidak ada bekas tertimpa cairan ataupun gangguan | G32: ='Input data'!G30 -> 1 | H32: Baik | I32: =IF(G32=1,"LULUS","TIDAK LULUS") -> LULUS | J32: =(COUNTIF(I32:I41,"LULUS")/(COUNTA(I32:I41))*100%) -> 1 | K32: =IF(J32>=70%,10,0) -> 10
H33: Tidak baik
C34: ='Input data'!C32 -> Kotak kontak alat | D34: ='Input data'!D32 -> periksa apakah ada gangguan pada kotak kontak (AC-Power). Gerak-gerakkan kotak kontak untuk memastikan keamanannya. Goyang-goyangkan kotak kontak untuk memastikan tidak ada baut atau mur yang longgar. | G34: ='Input data'!G32 -> 1 | H34: Baik | I34: =IF(G34=1,"LULUS","TIDAK LULUS") -> LULUS
H35: Tidak baik
C36: ='Input data'!C34 -> Kabel catu utama | D36: ='Input data'!D34 -> periksa kabel, apakah terlihat ada kerusakan atau bagian isolasi yang terkelupas. | G36: ='Input data'!G34 -> 1 | H36: Baik | I36: =IF(G36=1,"LULUS","TIDAK LULUS") -> LULUS
H37: Tidak baik
C38: ='Input data'!C36 -> Tombol, Saklar dan pengaman | D38: ='Input data'!D36 -> sebelum mempergunakan/mengubah-ubah tombol kontrol, periksa posisinya, jika terlihat tidak berada pada posisinya (periksa dengan menggunakan mode pemeriksaan standar). Bandingkan dengan posisi control. Ingat peraturan tersebut dan jangan lupa untuk mengembalikan pada setting awal jika sudah selesai menggunakan. | G38: ='Input data'!G36 -> 1 | H38: Baik | I38: =IF(G38=1,"LULUS","TIDAK LULUS") -> LULUS
H39: Tidak baik
C40: ='Input data'!C38 -> Tampilan indikator | D40: ='Input data'!D38 -> Pastikan lampu indikator dan bagian tampilan digital berfungsi seluruhnya | G40: ='Input data'!G38 -> 1 | H40: Baik | I40: =IF(G40=1,"LULUS","TIDAK LULUS") -> LULUS
H41: Tidak baik
B43: E. PENGUKURAN KESELAMATAN LISTRIK
B44: No | C44: Parameter | F44: Terukur | G44: Terkoreksi | H44: Memenuhi | J44: Ambang Batas | M44: KETERANGAN | N44: Bobot
H45: Ya | I45: Tidak
B46: 1 | C46: Resistansi pembumian protektif (Ω) | F46: ='Input data'!F51 -> 0.231 | G46: =VLOOKUP(G17,ESA!B5:Q5,13,FALSE)+VLOOKUP(G17,ESA!B5:Q5,14,FALSE)*F46 -> 0.22263429 | H46: √ | J46: ≤ | K46: 0.3 | L46: Ω | M46: =IF(G46<K46,"Aman","Tidak Aman") -> Aman | N46: =IF(COUNTIF((M46:M48),"Aman")<3,0,40) -> 40
B47: 2 | C47: Resistansi Isolasi (MΩ) | F47: ='Input data'!F52 -> OR | G47: =F47 -> OR | H47: √ | J47: > | K47: 2 | L47: MΩ | M47: =IF(G47>K47,"Aman","Tidak Aman") -> Aman
B48: 3 | C48: Arus bocor peralatan (µA) | F48: ='Input data'!F53 -> 0.9 | G48: =VLOOKUP(G17,ESA!B5:Q5,13,FALSE)+VLOOKUP(G17,ESA!B5:Q5,14,FALSE)*F48 -> 0.89197494 | H48: √ | J48: ≤ | K48: 500 | L48: µA | M48: =IF(G48<K48,"Aman","Tidak Aman") -> Aman
...

Sheet budget
B2: Glukosa | N2: Protein
B3: Komponen | C3: satuan | D3: Distribusi | E3: U | F3: Pembagi | G3: v | H3: u | I3: c | J3: (u.c) | K3: (u.c)² | L3: (u.c)⁴/v | N3: Komponen | O3: satuan | P3: Distribusi | Q3: U | R3: Pembagi | S3: v | T3: u | U3: c | V3: (u.c) | W3: (u.c)² | X3: (u.c)⁴/v
B4: Pengukuran berulang | C4: Mg/dl | D4: t-student | E4: =Skorsing!M54 -> 0.57735027 | F4: 1 | G4: 2 | H4: =E4/F4 -> 0.57735027 | I4: 1 | J4: =H4*I4 -> 0.57735027 | K4: =J4^2 -> 0.33333333 | L4: =J4^4/G4 -> 0.055555556 | N4: Pengukuran berulang | O4: Mg/dl | P4: t-student | Q4: =Skorsing!M55 -> 0.57735027 | R4: 1 | S4: 2 | T4: =Q4/R4 -> 0.57735027 | U4: 1 | V4: =T4*U4 -> 0.57735027 | W4: =V4^2 -> 0.33333333 | X4: =V4^4/S4 -> 0.055555556
B5: Sertifikat standar | C5: Mg/dl | D5: Normal | E5: 0 | F5: 2 | G5: =1/2*(100/10)^2 -> 50 | H5: =E5/F5 -> 0 | I5: 1 | J5: =H5*I5 -> 0 | K5: =J5^2 -> 0 | L5: =J5^4/G5 -> 0 | N5: Sertifikat standar | O5: Mg/dl | P5: Normal | Q5: 0 | R5: 2 | S5: =1/2*(100/10)^2 -> 50 | T5: =Q5/R5 -> 0 | U5: 1 | V5: =T5*U5 -> 0 | W5: =V5^2 -> 0 | X5: =V5^4/S5 -> 0
B6: Resolusi | C6: Mg/dl | D6: Rectangular | E6: =0.5*Skorsing!$D$11 -> 0.5 | F6: =SQRT(3) -> 1.7320508 | G6: =1/2*(100/10)^2 -> 50 | H6: =E6/F6 -> 0.28867513 | I6: 1 | J6: =H6*I6 -> 0.28867513 | K6: =J6^2 -> 0.083333333 | L6: =J6^4/G6 -> 0.00013888889 | N6: Resolusi | O6: Mg/dl | P6: Rectangular | Q6: =0.5*Skorsing!$D$11 -> 0.5 | R6: =SQRT(3) -> 1.7320508 | S6: =1/2*(100/10)^2 -> 50 | T6: =Q6/R6 -> 0.28867513 | U6: 1 | V6: =T6*U6 -> 0.28867513 | W6: =V6^2 -> 0.083333333 | X6: =V6^4/S6 -> 0.00013888889
B7: Drift | C7: Mg/dl | D7: Rectangular | E7: 0 | F7: =SQRT(3) -> 1.7320508 | G7: =1/2*(100/10)^2 -> 50 | H7: =E7/F7 -> 0 | I7: 1 | J7: =H7*I7 -> 0 | K7: =J7^2 -> 0 | L7: =J7^4/G7 -> 0 | N7: Drift | O7: Mg/dl | P7: Rectangular | Q7: 0 | R7: =SQRT(3) -> 1.7320508 | S7: =1/2*(100/10)^2 -> 50 | T7: =Q7/R7 -> 0 | U7: 1 | V7: =T7*U7 -> 0 | W7: =V7^2 -> 0 | X7: =V7^4/S7 -> 0
B8: Jumlah | K8: =SUM(K4:K7) -> 0.41666667 | L8: =SUM(L4:L7) -> 0.055694444 | N8: Jumlah | W8: =SUM(W4:W7) -> 0.41666667 | X8: =SUM(X4:X7) -> 0.055694444
B9: Ketidakpastian baku gabungan, Uc | K9: =SQRT(K8) -> 0.64549722 | N9: Ketidakpastian baku gabungan, Uc | W9: =SQRT(W8) -> 0.64549722
B10: Derajat kebebasan effektif, V eff | K10: =K9^4/L8 -> 3.117207 | N10: Derajat kebebasan effektif, V eff | W10: =W9^4/X8 -> 3.117207
B11: Faktor cakupan, k-student untuk Veff dan CL 95% | K11: =TINV(0.05,K10) -> 3.1824463 | N11: Faktor cakupan, k-student untuk Veff dan CL 95% | W11: =TINV(0.05,W10) -> 3.1824463
B12: Ketidakpastian bentangan, U=k.Uc | K12: =K11*K9 -> 2.0542603 | N12: Ketidakpastian bentangan, U=k.Uc | W12: =W11*W9 -> 2.0542603
B15: Ph | N15: Specific Gravity
B16: Komponen | C16: satuan | D16: Distribusi | E16: U | F16: Pembagi | G16: v | H16: u | I16: c | J16: (u.c) | K16: (u.c)² | L16: (u.c)⁴/v | N16: Komponen | O16: satuan | P16: Distribusi | Q16: U | R16: Pembagi | S16: v | T16: u | U16: c | V16: (u.c) | W16: (u.c)² | X16: (u.c)⁴/v
B17: Pengukuran berulang | C17: Mg/dl | D17: t-student | E17: =Skorsing!N56 -> 0.25819889 | F17: 1 | G17: 2 | H17: =E17/F17 -> 0.25819889 | I17: 1 | J17: =H17*I17 -> 0.25819889 | K17: =J17^2 -> 0.066666667 | L17: =J17^4/G17 -> 0.0022222222 | N17: Pengukuran berulang | O17: Mg/dl | P17: t-student | Q17: =Skorsing!M57 -> 1.1547005 | R17: 1 | S17: 2 | T17: =Q17/R17 -> 1.1547005 | U17: 1 | V17: =T17*U17 -> 1.1547005 | W17: =V17^2 -> 1.3333333 | X17: =V17^4/S17 -> 0.88888889
B18: Sertifikat standar | C18: Mg/dl | D18: Normal | E18: 0 | F18: 2 | G18: =1/2*(100/10)^2 -> 50 | H18: =E18/F18 -> 0 | I18: 1 | J18: =H18*I18 -> 0 | K18: =J18^2 -> 0 | L18: =J18^4/G18 -> 0 | N18: Sertifikat standar | O18: Mg/dl | P18: Normal | Q18: 0 | R18: 2 | S18: =1/2*(100/10)^2 -> 50 | T18: =Q18/R18 -> 0 | U18: 1 | V18: =T18*U18 -> 0 | W18: =V18^2 -> 0 | X18: =V18^4/S18 -> 0
B19: Resolusi | C19: Mg/dl | D19: Rectangular | E19: =0.5*Skorsing!$D$11 -> 0.5 | F19: =SQRT(3) -> 1.7320508 | G19: =1/2*(100/10)^2 -> 50 | H19: =E19/F19 -> 0.28867513 | I19: 1 | J19: =H19*I19 -> 0.28867513 | K19: =J19^2 -> 0.083333333 | L19: =J19^4/G19 -> 0.00013888889 | N19: Resolusi | O19: Mg/dl | P19: Rectangular | Q19: =0.5*Skorsing!$D$11 -> 0.5 | R19: =SQRT(3) -> 1.7320508 | S19: =1/2*(100/10)^2 -> 50 | T19: =Q19/R19 -> 0.28867513 | U19: 1 | V19: =T19*U19 -> 0.28867513 | W19: =V19^2 -> 0.083333333 | X19: =V19^4/S19 -> 0.00013888889
B20: Drift | C20: Mg/dl | D20: Rectangular | E20: 0 | F20: =SQRT(3) -> 1.7320508 | G20: =1/2*(100/10)^2 -> 50 | H20: =E20/F20 -> 0 | I20: 1 | J20: =H20*I20 -> 0 | K20: =J20^2 -> 0 | L20: =J20^4/G20 -> 0 | N20: Drift | O20: Mg/dl | P20: Rectangular | Q20: 0 | R20: =SQRT(3) -> 1.7320508 | S20: =1/2*(100/10)^2 -> 50 | T20: =Q20/R20 -> 0 | U20: 1 | V20: =T20*U20 -> 0 | W20: =V20^2 -> 0 | X20: =V20^4/S20 -> 0
B21: Jumlah | K21: =SUM(K17:K20) -> 0.15 | L21: =SUM(L17:L20) -> 0.0023611111 | N21: Jumlah | W21: =SUM(W17:W20) -> 1.4166667 | X21: =SUM(X17:X20) -> 0.88902778
B22: Ketidakpastian baku gabungan, Uc | K22: =SQRT(K21) -> 0.38729833 | N22: Ketidakpastian baku gabungan, Uc | W22: =SQRT(W21) -> 1.1902381
B23: Derajat kebebasan effektif, V eff | K23: =K22^4/L21 -> 9.5294118 | N23: Derajat kebebasan effektif, V eff | W23: =W22^4/X21 -> 2.2574598
B24: Faktor cakupan, k-student untuk Veff dan CL 95% | K24: =TINV(0.05,K23) -> 2.2621572 | N24: Faktor cakupan, k-student untuk Veff dan CL 95% | W24: =TINV(0.05,W23) -> 4.3026527
B25: Ketidakpastian bentangan, U=k.Uc | K25: =K24*K22 -> 0.8761297 | N25: Ketidakpastian bentangan, U=k.Uc | W25: =W24*W22 -> 5.1211811
B28: Blood / Erythrocyte | N28: Leukosit
B29: Komponen | C29: satuan | D29: Distribusi | E29: U | F29: Pembagi | G29: v | H29: u | I29: c | J29: (u.c) | K29: (u.c)² | L29: (u.c)⁴/v | N29: Komponen | O29: satuan | P29: Distribusi | Q29: U | R29: Pembagi | S29: v | T29: u | U29: c | V29: (u.c) | W29: (u.c)² | X29: (u.c)⁴/v
B30: Pengukuran berulang | C30: Mg/dl | D30: t-student | E30: =Skorsing!M58 -> 0.57735027 | F30: 1 | G30: 2 | H30: =E30/F30 -> 0.57735027 | I30: 1 | J30: =H30*I30 -> 0.57735027 | K30: =J30^2 -> 0.33333333 | L30: =J30^4/G30 -> 0.055555556 | N30: Pengukuran berulang | O30: Mg/dl | P30: t-student | Q30: =Skorsing!M59 -> 0.57735027 | R30: 1 | S30: 2 | T30: =Q30/R30 -> 0.57735027 | U30: 1 | V30: =T30*U30 -> 0.57735027 | W30: =V30^2 -> 0.33333333 | X30: =V30^4/S30 -> 0.055555556
B31: Sertifikat standar | C31: Mg/dl | D31: Normal | E31: 0 | F31: 2 | G31: =1/2*(100/10)^2 -> 50 | H31: =E31/F31 -> 0 | I31: 1 | J31: =H31*I31 -> 0 | K31: =J31^2 -> 0 | L31: =J31^4/G31 -> 0 | N31: Sertifikat standar | O31: Mg/dl | P31: Normal | Q31: 0 | R31: 2 | S31: =1/2*(100/10)^2 -> 50 | T31: =Q31/R31 -> 0 | U31: 1 | V31: =T31*U31 -> 0 | W31: =V31^2 -> 0 | X31: =V31^4/S31 -> 0
B32: Resolusi | C32: Mg/dl | D32: Rectangular | E32: =0.5*Skorsing!$D$11 -> 0.5 | F32: =SQRT(3) -> 1.7320508 | G32: =1/2*(100/10)^2 -> 50 | H32: =E32/F32 -> 0.28867513 | I32: 1 | J32: =H32*I32 -> 0.28867513 | K32: =J32^2 -> 0.083333333 | L32: =J32^4/G32 -> 0.00013888889 | N32: Resolusi | O32: Mg/dl | P32: Rectangular | Q32: =0.5*Skorsing!$D$11 -> 0.5 | R32: =SQRT(3) -> 1.7320508 | S32: =1/2*(100/10)^2 -> 50 | T32: =Q32/R32 -> 0.28867513 | U32: 1 | V32: =T32*U32 -> 0.28867513 | W32: =V32^2 -> 0.083333333 | X32: =V32^4/S32 -> 0.00013888889
B33: Drift | C33: Mg/dl | D33: Rectangular | E33: 0 | F33: =SQRT(3) -> 1.7320508 | G33: =1/2*(100/10)^2 -> 50 | H33: =E33/F33 -> 0 | I33: 1 | J33: =H33*I33 -> 0 | K33: =J33^2 -> 0 | L33: =J33^4/G33 -> 0 | N33: Drift | O33: Mg/dl | P33: Rectangular | Q33: 0 | R33: =SQRT(3) -> 1.7320508 | S33: =1/2*(100/10)^2 -> 50 | T33: =Q33/R33 -> 0 | U33: 1 | V33: =T33*U33 -> 0 | W33: =V33^2 -> 0 | X33: =V33^4/S33 -> 0
B34: Jumlah | K34: =SUM(K30:K33) -> 0.41666667 | L34: =SUM(L30:L33) -> 0.055694444 | N34: Jumlah | W34: =SUM(W30:W33) -> 0.41666667 | X34: =SUM(X30:X33) -> 0.055694444
B35: Ketidakpastian baku gabungan, Uc | K35: =SQRT(K34) -> 0.64549722 | N35: Ketidakpastian baku gabungan, Uc | W35: =SQRT(W34) -> 0.64549722
B36: Derajat kebebasan effektif, V eff | K36: =K35^4/L34 -> 3.117207 | N36: Derajat kebebasan effektif, V eff | W36: =W35^4/X34 -> 3.117207
B37: Faktor cakupan, k-student untuk Veff dan CL 95% | K37: =TINV(0.05,K36) -> 3.1824463 | N37: Faktor cakupan, k-student untuk Veff dan CL 95% | W37: =TINV(0.05,W36) -> 3.1824463
B38: Ketidakpastian bentangan, U=k.Uc | K38: =K37*K35 -> 2.0542603 | N38: Ketidakpastian bentangan, U=k.Uc | W38: =W37*W35 -> 2.0542603
B41: Nitrit | N41: Keton
B42: Komponen | C42: satuan | D42: Distribusi | E42: U | F42: Pembagi | G42: v | H42: u | I42: c | J42: (u.c) | K42: (u.c)² | L42: (u.c)⁴/v | N42: Komponen | O42: satuan | P42: Distribusi | Q42: U | R42: Pembagi | S42: v | T42: u | U42: c | V42: (u.c) | W42: (u.c)² | X42: (u.c)⁴/v
B43: Pengukuran berulang | C43: Mg/dl | D43: t-student | E43: =Skorsing!M60 -> 0.57735027 | F43: 1 | G43: 2 | H43: =E43/F43 -> 0.57735027 | I43: 1 | J43: =H43*I43 -> 0.57735027 | K43: =J43^2 -> 0.33333333 | L43: =J43^4/G43 -> 0.055555556 | N43: Pengukuran berulang | O43: Mg/dl | P43: t-student | Q43: =Skorsing!M61 -> 0.57735027 | R43: 1 | S43: 2 | T43: =Q43/R43 -> 0.57735027 | U43: 1 | V43: =T43*U43 -> 0.57735027 | W43: =V43^2 -> 0.33333333 | X43: =V43^4/S43 -> 0.055555556
B44: Sertifikat standar | C44: Mg/dl | D44: Normal | E44: 0 | F44: 2 | G44: =1/2*(100/10)^2 -> 50 | H44: =E44/F44 -> 0 | I44: 1 | J44: =H44*I44 -> 0 | K44: =J44^2 -> 0 | L44: =J44^4/G44 -> 0 | N44: Sertifikat standar | O44: Mg/dl | P44: Normal | Q44: 0 | R44: 2 | S44: =1/2*(100/10)^2 -> 50 | T44: =Q44/R44 -> 0 | U44: 1 | V44: =T44*U44 -> 0 | W44: =V44^2 -> 0 | X44: =V44^4/S44 -> 0
B45: Resolusi | C45: Mg/dl | D45: Rectangular | E45: =0.5*Skorsing!$D$11 -> 0.5 | F45: =SQRT(3) -> 1.7320508 | G45: =1/2*(100/10)^2 -> 50 | H45: =E45/F45 -> 0.28867513 | I45: 1 | J45: =H45*I45 -> 0.28867513 | K45: =J45^2 -> 0.083333333 | L45: =J45^4/G45 -> 0.00013888889 | N45: Resolusi | O45: Mg/dl | P45: Rectangular | Q45: =0.5*Skorsing!$D$11 -> 0.5 | R45: =SQRT(3) -> 1.7320508 | S45: =1/2*(100/10)^2 -> 50 | T45: =Q45/R45 -> 0.28867513 | U45: 1 | V45: =T45*U45 -> 0.28867513 | W45: =V45^2 -> 0.083333333 | X45: =V45^4/S45 -> 0.00013888889
B46: Drift | C46: Mg/dl | D46: Rectangular | E46: 0 | F46: =SQRT(3) -> 1.7320508 | G46: =1/2*(100/10)^2 -> 50 | H46: =E46/F46 -> 0 | I46: 1 | J46: =H46*I46 -> 0 | K46: =J46^2 -> 0 | L46: =J46^4/G46 -> 0 | N46: Drift | O46: Mg/dl | P46: Rectangular | Q46: 0 | R46: =SQRT(3) -> 1.7320508 | S46: =1/2*(100/10)^2 -> 50 | T46: =Q46/R46 -> 0 | U46: 1 | V46: =T46*U46 -> 0 | W46: =V46^2 -> 0 | X46: =V46^4/S46 -> 0
B47: Jumlah | K47: =SUM(K43:K46) -> 0.41666667 | L47: =SUM(L43:L46) -> 0.055694444 | N47: Jumlah | W47: =SUM(W43:W46) -> 0.41666667 | X47: =SUM(X43:X46) -> 0.055694444
...

Sheet ESA
B2: 1 | C2: 2 | D2: 3 | E2: 4 | F2: 5 | G2: 6 | H2: 7 | I2: 8 | J2: 9 | K2: 10 | L2: 11 | M2: 12 | N2: 13 | O2: 14 | P2: 15 | Q2: 16
B3: =[3]ARRAY!C5 -> No. Seri | C3: =[3]ARRAY!D5 -> No | D3: =[3]ARRAY!E5 -> Merk | E3: =[3]ARRAY!F5 -> Type | F3: =[3]ARRAY!G5 -> Tanggal Kalibrasi | G3: =[3]ARRAY!H5 -> Tertelusur | H3: =[3]ARRAY!I5 -> Tegangan | J3: =[3]ARRAY!K5 -> Arus DC (µA) | L3: =[3]ARRAY!M5 -> Arus AC (µA) | N3: =[3]ARRAY!O5 -> Resistansi Pembumian (Ω) | P3: =[3]ARRAY!Q5 -> Resistansi Isolasi (MΩ)
H4: =[3]ARRAY!I6 -> Intercept | I4: =[3]ARRAY!J6 -> Variabel X | J4: =[3]ARRAY!K6 -> Intercept | K4: =[3]ARRAY!L6 -> Variabel X | L4: =[3]ARRAY!M6 -> Intercept | M4: =[3]ARRAY!N6 -> Variabel X | N4: =[3]ARRAY!O6 -> Intercept | O4: =[3]ARRAY!P6 -> Variabel X | ... Q4: =[3]ARRAY!R6 -> Variabel X
B5: =[3]ARRAY!C7 -> 6579027 | C5: =[3]ARRAY!D7 -> 1 | D5: =[3]ARRAY!E7 -> Fluke Biomedical | E5: =[3]ARRAY!F7 -> ESA16 | F5: =[3]ARRAY!G7 -> 45819 | G5: =[3]ARRAY!H7 -> LK-110-IDN | H5: =[3]ARRAY!I7 -> 0.18884844 | I5: =[3]ARRAY!J7 -> 0.99976434 | ... Q5: =[3]ARRAY!R7 -> 1
B10: 1 | C10: 2 | D10: 3 | E10: 4 | F10: 5 | G10: 6 | H10: 7 | I10: 8
B11: =B3 -> No. Seri | C11: =C3 -> No | D11: =D3 -> Merk | E11: =E3 -> Type | F11: Tegangan | G11: Arus Bocor peralatan (µA) | H11: Resistansi Pembumian (Ω) | I11: Resistansi Isolasi (MΩ)
B12: =B5 -> 6579027 | C12: =C5 -> 1 | D12: =D5 -> Fluke Biomedical | E12: =E5 -> ESA16 | F12: =VLOOKUP(Skorsing!G17,ESA!B5:Q5,7,FALSE)+VLOOKUP(Skorsing!G17,ESA!B5:Q5,8,FALSE)*Skorsing!E25 -> 221.23674 | G12: =VLOOKUP(Skorsing!G17,ESA!B5:Q5,11,FALSE)+VLOOKUP(Skorsing!G17,ESA!B5:Q5,12,FALSE)*Skorsing!F48 -> 0.91280836 | H12: =VLOOKUP(Skorsing!G17,ESA!B5:Q5,13,FALSE)+VLOOKUP(Skorsing!G17,ESA!B5:Q5,14,FALSE)*Skorsing!F46 -> 0.22263429 | I12: =Skorsing!F47 -> OR

Sheet laporan
B2: ='Input data'!D6 -> Urine Analyzer
A4: A. PENDATAAN ADMINISTRASI
B5: Nama Pelanggan : | C5: ='Input data'!D5 -> S.612 | D5: Resolusi : | E5: ='Input data'!D11 -> 1
B6: Nama Alat : | C6: ='Input data'!D6 -> Urine Analyzer | D6: Rentang Ukur : | E6: ='Input data'!D10 -> 0
D7: Ruangan Tempat Alat : | E7: ='Input data'!H6 -> PT. Presisi Kalibrasi Medika
B8: Merek : | C8: ='Input data'!D7 -> SM | D8: Tgl. Terima | E8: ='Input data'!H8 -> 46266
B9: Model/Tipe : | C9: ='Input data'!D8 -> SM S-600 | D9: Tgl. Kalibrasi | E9: ='Input data'!H9 -> 46266
B10: No. Seri : | C10: ='Input data'!D9 -> 111 | D10: Nama Petugas Kalibrasi : | E10: ='Input data'!H10 -> el
A13: B. DAFTAR ALAT YANG DIGUNAKAN
A14: No | B14: Nama Alat | D14: Merk | E14: Tipe / Model | F14: No. Seri
A15: 1 | B15: =Skorsing!C16 -> Kontrol Standard / CRM | D15: =Skorsing!E16 -> - | E15: =Skorsing!F16 -> - | F15: =Skorsing!G16 -> -
A16: 2 | B16: =Skorsing!C17 -> Electrical Safety Analyzer | D16: =Skorsing!E17 -> Fluke Biomedical | E16: =Skorsing!F17 -> ESA612 | F16: =Skorsing!G17 -> 6579027
A17: 3 | B17: =Skorsing!C18 -> Thermohygrometer | D17: =Skorsing!E18 -> Taffware | E17: =Skorsing!F18 -> HTC-1 | F17: =Skorsing!G18 -> TH-01
A19: C. PENGUKURAN KONDISI LINGKUNGAN
B20: Kondisi Ruang | C20: terkoreksi | D20: ktps
B21: Suhu (°C) | C21: =Skorsing!H23 -> 23.750549 | D21: =Skorsing!I23 -> 0.5
B22: RH (%) | C22: =Skorsing!H24 -> 53.618909 | D22: =Skorsing!I24 -> 2.7
B23: Tegangan | C23: =Skorsing!H25 -> 221.23674
A25: D. PEMERIKSAAN FISIK DAN FUNGSI ALAT
B26: Bagian Alat | C26: Keterangan | F26: Hasil Pengamatan
B27: ='Input data'!C30 -> Badan Permukaan | C27: ='Input data'!D30 -> Selungkup utuh, bersih, terpasang ketat satu dan yang lainnya serta tidak ada bekas tertimpa cairan ataupun gangguan | F27: =IF(Skorsing!G32=1,"BAIK","TIDAK BAIK") -> BAIK
B29: ='Input data'!C32 -> Kotak kontak alat | C29: ='Input data'!D32 -> periksa apakah ada gangguan pada kotak kontak (AC-Power). Gerak-gerakkan kotak kontak untuk memastikan keamanannya. Goyang-goyangkan kotak kontak untuk memastikan tidak ada baut atau mur yang longgar. | F29: =IF(Skorsing!G34=1,"BAIK","TIDAK BAIK") -> BAIK
B31: ='Input data'!C34 -> Kabel catu utama | C31: ='Input data'!D34 -> periksa kabel, apakah terlihat ada kerusakan atau bagian isolasi yang terkelupas. | F31: =IF(Skorsing!G36=1,"BAIK","TIDAK BAIK") -> BAIK
B33: ='Input data'!C36 -> Tombol, Saklar dan pengaman | C33: ='Input data'!D36 -> sebelum mempergunakan/mengubah-ubah tombol kontrol, periksa posisinya, jika terlihat tidak berada pada posisinya (periksa dengan menggunakan mode pemeriksaan standar). Bandingkan dengan posisi control. Ingat peraturan tersebut dan jangan lupa untuk mengembalikan pada setting awal jika sudah selesai menggunakan. | F33: =IF(Skorsing!G38=1,"BAIK","TIDAK BAIK") -> BAIK
B35: ='Input data'!C38 -> Tampilan indikator | C35: ='Input data'!D38 -> Pastikan lampu indikator dan bagian tampilan digital berfungsi seluruhnya | F35: =IF(Skorsing!G40=1,"BAIK","TIDAK BAIK") -> BAIK
A38: E. PENGUKURAN KESELAMATAN LISTRIK
A39: No. | B39: Parameter | C39: Terukur Koreksi | D39: Memenuhi
D40: Ya | E40: Tidak
A41: 1 | B41: =[4]skorsing!B60 -> 1 | C41: =Skorsing!G46 -> 0.22263429 | D41: =Skorsing!H46 -> √
A43: 2 | B43: =[4]skorsing!B61 -> 2 | C43: =Skorsing!G47 -> OR | D43: =Skorsing!H47 -> √
A45: 3 | B45: =[4]skorsing!B62 -> 3 | C45: =Skorsing!G48 -> 0.89197494 | D45: =Skorsing!H48 -> √
A49: F. PENGUKURAN KINERJA ALAT
A50: 1. Pengujian Kinerja
A51: Parameter | C51: Hasil Pembacaan | D51: Ketidakpastian
A52: =Skorsing!C54 -> Glukosa | C52: =Skorsing!L54 -> 1.3333333 | D52: =Skorsing!O54 -> 2.0542603
A53: =Skorsing!C55 -> Protein | C53: =Skorsing!L55 -> 2.3333333 | D53: =Skorsing!O55 -> 2.0542603
A54: =Skorsing!C56 -> Ph | C54: =Skorsing!L56 -> 3.6666667 | D54: =Skorsing!O56 -> 0.8761297
A55: =Skorsing!C57 -> Specific Gravity | C55: =Skorsing!L57 -> 1.6666667 | D55: =Skorsing!O57 -> 5.1211811
A56: =Skorsing!C58 -> Blood / Erythrocyte | C56: =Skorsing!L58 -> 4.3333333 | D56: =Skorsing!O58 -> 2.0542603
A57: =Skorsing!C59 -> Leukosit | C57: =Skorsing!L59 -> 4.3333333 | D57: =Skorsing!O59 -> 2.0542603
...

Sheet Laporan Print 
L8: Nomor Sertifikat | P8: : | Q8: ='Cover '!Q8:S8 -> S.612
L9: Certificate Number
A12: LAPORAN KALIBRASI
A13: Calibration Report
A14: =laporan!C6 -> Urine Analyzer
A16: A. | B16: PENDATAAN ADMINISTRASI
B17: Administration
B18: Merk | I18: : | J18: =laporan!C8 -> SM
B19: Brand
B20: Type/Model | I20: : | J20: =laporan!C9 -> SM S-600
B21: Type/Model
B22: Nomor Seri | I22: : | J22: =laporan!C10 -> 111
B23: Serial Number
B24: Resolusi | I24: : | J24: =laporan!E5 -> 1
B25: Resolution
B26: Ruangan Alat | I26: : | J26: =laporan!E7 -> PT. Presisi Kalibrasi Medika
B27: Instrument Location
B28: Tanggal Penerimaan Alat | I28: : | J28: =laporan!E8 -> 46266
B29: Order Received
B30: Tanggal Kalibrasi | I30: : | J30: =laporan!E9 -> 46266
B31: Calibration Date
B32: Berlaku Sampai Dengan | I32: :
B33: Valid Until
A35: B. | B35: KONDISI RUANGAN
B36: Environment Condition
B37: 1 | C37: Suhu | I37: : | J37: ( | K37: =laporan!C21 -> 23.750549 | L37: ± | M37: =[5]Laporan!E22 -> 0.5 | N37: )°C
C38: Temperature
B39: 2 | C39: Kelembaban | I39: : | J39: ( | K39: =laporan!C22 -> 53.618909 | L39: ± | M39: =[5]Laporan!E23 -> 2.7 | N39: )%RH
C40: Humidity
C41: Sumber Tegangan | H41: L-N | I41: : | J41: =laporan!C23 -> 221.23674 | L41: Vac
C42: Power Supply Voltage
A48: C. | B48: PENGAMATAN KONDISI FISIK DAN FUNGSI
B49: Physcal And Function Inspection Result
B50: 1 | C50: Fisik Alat | I50: : | J50: =laporan!E70 -> Baik | K50: / | L50: Good
C51: Instrument Physical
B52: 2 | C52: Fungsi Alat | I52: : | J52: =laporan!E70 -> Baik | K52: / | L52: Good
C53: Instrument Function
A55: D. | B55: DAFTAR ALAT YANG DIGUNAKAN
B56: List Of Instrument Standard
B57: Nama Alat | H57: Merk | L57: Model/Type | O57: Nomor Seri
...

Sheet Cover 
L8: Nomor Sertifikat | P8: : | Q8: =Skorsing!D5 -> S.612
L9: Certificate Number
A11: SERTIFIKAT KALIBRASI
A12: Calibration Certificate
B13: DATA ALAT
B14: Instrument ID
C15: Nama Alat | F15: : | G15: =laporan!C6 -> Urine Analyzer
C16: Device Name
C17: Merk | F17: : | G17: =laporan!C8 -> SM
C18: Brand
C19: Type/Model | F19: : | G19: =laporan!C9 -> SM S-600
C20: Type/Model
C21: Nomor Seri | F21: : | G21: =laporan!C10 -> 111
C22: Serial Number
C23: Resolusi | F23: : | G23: =laporan!E5 -> 1
C24: Resolution
B26: IDENTITAS PELANGGAN
B27: Customer ID
C28: Pelanggan | F28: : | G28: =laporan!E7 -> PT. Presisi Kalibrasi Medika
C29: Customer
C30: Alamat | F30: :
C31: Address
I33: Sertifikat ini terdiri dari | N33: : | O33: 5 halaman
I34: This certificate consist of
I35: Diterbitkan tanggal | N35: :
I36: Published date
K38: PT. Presisi Kalibrasi Medika
K42: Samsurizal
K43: Direktur
K44: Director
